<?xml version="1.0" ?>
<!-- =================================================================================== -->
<!-- |    This document was autogenerated by xacro from ssl_robot2.xacro               | -->
<!-- |    EDITING THIS FILE BY HAND IS NOT RECOMMENDED                                 | -->
<!-- =================================================================================== -->
<robot name="ssl_robot" xmlns:xacro="http://www.ros.org/wiki/xacro">
  <!-- ros_control plugin -->
  <gazebo>
    <plugin filename="libgazebo_ros_control.so" name="gazebo_ros_control">
      <robotNamespace>/ssl_robot</robotNamespace>
    </plugin>
    <static>false</static>
  </gazebo>
  <gazebo reference="base_link">
    <material>Gazebo/White</material>
  </gazebo>
  <gazebo reference="sub_wheel_fl_1">
    <mu>44</mu>
    <mu2>2</mu2>
    <fdir1>0 0 0</fdir1>
    <dampingFactor>0.43</dampingFactor>
  </gazebo>
  <gazebo reference="sub_wheel_fr_1">
    <mu>44</mu>
    <mu2>2</mu2>
    <fdir1>0 0 0</fdir1>
    <dampingFactor>0.43</dampingFactor>
  </gazebo>
  <gazebo reference="sub_wheel_rl_1">
    <mu>44</mu>
    <mu2>2</mu2>
    <fdir1>0 0 0</fdir1>
    <dampingFactor>0.43</dampingFactor>
  </gazebo>
  <gazebo reference="sub_wheel_rr_1">
    <mu>44</mu>
    <mu2>2</mu2>
    <fdir1>0 0 0</fdir1>
    <dampingFactor>0.43</dampingFactor>
  </gazebo>
  <gazebo reference="sub_wheel_fl_2">
    <mu>44</mu>
    <mu2>2</mu2>
    <fdir1>0 0 0</fdir1>
    <dampingFactor>0.43</dampingFactor>
  </gazebo>
  <gazebo reference="sub_wheel_fr_2">
    <mu>44</mu>
    <mu2>2</mu2>
    <fdir1>0 0 0</fdir1>
    <dampingFactor>0.43</dampingFactor>
  </gazebo>
  <gazebo reference="sub_wheel_rl_2">
    <mu>44</mu>
    <mu2>2</mu2>
    <fdir1>0 0 0</fdir1>
    <dampingFactor>0.43</dampingFactor>
  </gazebo>
  <gazebo reference="sub_wheel_rr_2">
    <mu>44</mu>
    <mu2>2</mu2>
    <fdir1>0 0 0</fdir1>
    <dampingFactor>0.43</dampingFactor>
  </gazebo>
  <gazebo reference="sub_wheel_fl_3">
    <mu>44</mu>
    <mu2>2</mu2>
    <fdir1>0 0 0</fdir1>
    <dampingFactor>0.43</dampingFactor>
  </gazebo>
  <gazebo reference="sub_wheel_fr_3">
    <mu>44</mu>
    <mu2>2</mu2>
    <fdir1>0 0 0</fdir1>
    <dampingFactor>0.43</dampingFactor>
  </gazebo>
  <gazebo reference="sub_wheel_rl_3">
    <mu>44</mu>
    <mu2>2</mu2>
    <fdir1>0 0 0</fdir1>
    <dampingFactor>0.43</dampingFactor>
  </gazebo>
  <gazebo reference="sub_wheel_rr_3">
    <mu>44</mu>
    <mu2>2</mu2>
    <fdir1>0 0 0</fdir1>
    <dampingFactor>0.43</dampingFactor>
  </gazebo>
  <gazebo reference="sub_wheel_fl_4">
    <mu>44</mu>
    <mu2>2</mu2>
    <fdir1>0 0 0</fdir1>
    <dampingFactor>0.43</dampingFactor>
  </gazebo>
  <gazebo reference="sub_wheel_fr_4">
    <mu>44</mu>
    <mu2>2</mu2>
    <fdir1>0 0 0</fdir1>
    <dampingFactor>0.43</dampingFactor>
  </gazebo>
  <gazebo reference="sub_wheel_rl_4">
    <mu>44</mu>
    <mu2>2</mu2>
    <fdir1>0 0 0</fdir1>
    <dampingFactor>0.43</dampingFactor>
  </gazebo>
  <gazebo reference="sub_wheel_rr_4">
    <mu>44</mu>
    <mu2>2</mu2>
    <fdir1>0 0 0</fdir1>
    <dampingFactor>0.43</dampingFactor>
  </gazebo>
  <gazebo reference="sub_wheel_fl_5">
    <mu>44</mu>
    <mu2>2</mu2>
    <fdir1>0 0 0</fdir1>
    <dampingFactor>0.43</dampingFactor>
  </gazebo>
  <gazebo reference="sub_wheel_fr_5">
    <mu>44</mu>
    <mu2>2</mu2>
    <fdir1>0 0 0</fdir1>
    <dampingFactor>0.43</dampingFactor>
  </gazebo>
  <gazebo reference="sub_wheel_rl_5">
    <mu>44</mu>
    <mu2>2</mu2>
    <fdir1>0 0 0</fdir1>
    <dampingFactor>0.43</dampingFactor>
  </gazebo>
  <gazebo reference="sub_wheel_rr_5">
    <mu>44</mu>
    <mu2>2</mu2>
    <fdir1>0 0 0</fdir1>
    <dampingFactor>0.43</dampingFactor>
  </gazebo>
  <gazebo reference="sub_wheel_fl_6">
    <mu>44</mu>
    <mu2>2</mu2>
    <fdir1>0 0 0</fdir1>
    <dampingFactor>0.43</dampingFactor>
  </gazebo>
  <gazebo reference="sub_wheel_fr_6">
    <mu>44</mu>
    <mu2>2</mu2>
    <fdir1>0 0 0</fdir1>
    <dampingFactor>0.43</dampingFactor>
  </gazebo>
  <gazebo reference="sub_wheel_rl_6">
    <mu>44</mu>
    <mu2>2</mu2>
    <fdir1>0 0 0</fdir1>
    <dampingFactor>0.43</dampingFactor>
  </gazebo>
  <gazebo reference="sub_wheel_rr_6">
    <mu>44</mu>
    <mu2>2</mu2>
    <fdir1>0 0 0</fdir1>
    <dampingFactor>0.43</dampingFactor>
  </gazebo>
  <gazebo reference="sub_wheel_fl_7">
    <mu>44</mu>
    <mu2>2</mu2>
    <fdir1>0 0 0</fdir1>
    <dampingFactor>0.43</dampingFactor>
  </gazebo>
  <gazebo reference="sub_wheel_fr_7">
    <mu>44</mu>
    <mu2>2</mu2>
    <fdir1>0 0 0</fdir1>
    <dampingFactor>0.43</dampingFactor>
  </gazebo>
  <gazebo reference="sub_wheel_rl_7">
    <mu>44</mu>
    <mu2>2</mu2>
    <fdir1>0 0 0</fdir1>
    <dampingFactor>0.43</dampingFactor>
  </gazebo>
  <gazebo reference="sub_wheel_rr_7">
    <mu>44</mu>
    <mu2>2</mu2>
    <fdir1>0 0 0</fdir1>
    <dampingFactor>0.43</dampingFactor>
  </gazebo>
  <gazebo reference="sub_wheel_fl_8">
    <mu>44</mu>
    <mu2>2</mu2>
    <fdir1>0 0 0</fdir1>
    <dampingFactor>0.43</dampingFactor>
  </gazebo>
  <gazebo reference="sub_wheel_fr_8">
    <mu>44</mu>
    <mu2>2</mu2>
    <fdir1>0 0 0</fdir1>
    <dampingFactor>0.43</dampingFactor>
  </gazebo>
  <gazebo reference="sub_wheel_rl_8">
    <mu>44</mu>
    <mu2>2</mu2>
    <fdir1>0 0 0</fdir1>
    <dampingFactor>0.43</dampingFactor>
  </gazebo>
  <gazebo reference="sub_wheel_rr_8">
    <mu>44</mu>
    <mu2>2</mu2>
    <fdir1>0 0 0</fdir1>
    <dampingFactor>0.43</dampingFactor>
  </gazebo>
  <gazebo reference="sub_wheel_fl_9">
    <mu>44</mu>
    <mu2>2</mu2>
    <fdir1>0 0 0</fdir1>
    <dampingFactor>0.43</dampingFactor>
  </gazebo>
  <gazebo reference="sub_wheel_fr_9">
    <mu>44</mu>
    <mu2>2</mu2>
    <fdir1>0 0 0</fdir1>
    <dampingFactor>0.43</dampingFactor>
  </gazebo>
  <gazebo reference="sub_wheel_rl_9">
    <mu>44</mu>
    <mu2>2</mu2>
    <fdir1>0 0 0</fdir1>
    <dampingFactor>0.43</dampingFactor>
  </gazebo>
  <gazebo reference="sub_wheel_rr_9">
    <mu>44</mu>
    <mu2>2</mu2>
    <fdir1>0 0 0</fdir1>
    <dampingFactor>0.43</dampingFactor>
  </gazebo>
  <gazebo reference="sub_wheel_fl_10">
    <mu>44</mu>
    <mu2>2</mu2>
    <fdir1>0 0 0</fdir1>
    <dampingFactor>0.43</dampingFactor>
  </gazebo>
  <gazebo reference="sub_wheel_fr_10">
    <mu>44</mu>
    <mu2>2</mu2>
    <fdir1>0 0 0</fdir1>
    <dampingFactor>0.43</dampingFactor>
  </gazebo>
  <gazebo reference="sub_wheel_rl_10">
    <mu>44</mu>
    <mu2>2</mu2>
    <fdir1>0 0 0</fdir1>
    <dampingFactor>0.43</dampingFactor>
  </gazebo>
  <gazebo reference="sub_wheel_rr_10">
    <mu>44</mu>
    <mu2>2</mu2>
    <fdir1>0 0 0</fdir1>
    <dampingFactor>0.43</dampingFactor>
  </gazebo>
  <gazebo reference="sub_wheel_fl_11">
    <mu>44</mu>
    <mu2>2</mu2>
    <fdir1>0 0 0</fdir1>
    <dampingFactor>0.43</dampingFactor>
  </gazebo>
  <gazebo reference="sub_wheel_fr_11">
    <mu>44</mu>
    <mu2>2</mu2>
    <fdir1>0 0 0</fdir1>
    <dampingFactor>0.43</dampingFactor>
  </gazebo>
  <gazebo reference="sub_wheel_rl_11">
    <mu>44</mu>
    <mu2>2</mu2>
    <fdir1>0 0 0</fdir1>
    <dampingFactor>0.43</dampingFactor>
  </gazebo>
  <gazebo reference="sub_wheel_rr_11">
    <mu>44</mu>
    <mu2>2</mu2>
    <fdir1>0 0 0</fdir1>
    <dampingFactor>0.43</dampingFactor>
  </gazebo>
  <gazebo reference="sub_wheel_fl_12">
    <mu>44</mu>
    <mu2>2</mu2>
    <fdir1>0 0 0</fdir1>
    <dampingFactor>0.43</dampingFactor>
  </gazebo>
  <gazebo reference="sub_wheel_fr_12">
    <mu>44</mu>
    <mu2>2</mu2>
    <fdir1>0 0 0</fdir1>
    <dampingFactor>0.43</dampingFactor>
  </gazebo>
  <gazebo reference="sub_wheel_rl_12">
    <mu>44</mu>
    <mu2>2</mu2>
    <fdir1>0 0 0</fdir1>
    <dampingFactor>0.43</dampingFactor>
  </gazebo>
  <gazebo reference="sub_wheel_rr_12">
    <mu>44</mu>
    <mu2>2</mu2>
    <fdir1>0 0 0</fdir1>
    <dampingFactor>0.43</dampingFactor>
  </gazebo>
  <gazebo reference="sub_wheel_fl_13">
    <mu>44</mu>
    <mu2>2</mu2>
    <fdir1>0 0 0</fdir1>
    <dampingFactor>0.43</dampingFactor>
  </gazebo>
  <gazebo reference="sub_wheel_fr_13">
    <mu>44</mu>
    <mu2>2</mu2>
    <fdir1>0 0 0</fdir1>
    <dampingFactor>0.43</dampingFactor>
  </gazebo>
  <gazebo reference="sub_wheel_rl_13">
    <mu>44</mu>
    <mu2>2</mu2>
    <fdir1>0 0 0</fdir1>
    <dampingFactor>0.43</dampingFactor>
  </gazebo>
  <gazebo reference="sub_wheel_rr_13">
    <mu>44</mu>
    <mu2>2</mu2>
    <fdir1>0 0 0</fdir1>
    <dampingFactor>0.43</dampingFactor>
  </gazebo>
  <gazebo reference="sub_wheel_fl_14">
    <mu>44</mu>
    <mu2>2</mu2>
    <fdir1>0 0 0</fdir1>
    <dampingFactor>0.43</dampingFactor>
  </gazebo>
  <gazebo reference="sub_wheel_fr_14">
    <mu>44</mu>
    <mu2>2</mu2>
    <fdir1>0 0 0</fdir1>
    <dampingFactor>0.43</dampingFactor>
  </gazebo>
  <gazebo reference="sub_wheel_rl_14">
    <mu>44</mu>
    <mu2>2</mu2>
    <fdir1>0 0 0</fdir1>
    <dampingFactor>0.43</dampingFactor>
  </gazebo>
  <gazebo reference="sub_wheel_rr_14">
    <mu>44</mu>
    <mu2>2</mu2>
    <fdir1>0 0 0</fdir1>
    <dampingFactor>0.43</dampingFactor>
  </gazebo>
  <gazebo reference="sub_wheel_fl_15">
    <mu>44</mu>
    <mu2>2</mu2>
    <fdir1>0 0 0</fdir1>
    <dampingFactor>0.43</dampingFactor>
  </gazebo>
  <gazebo reference="sub_wheel_fr_15">
    <mu>44</mu>
    <mu2>2</mu2>
    <fdir1>0 0 0</fdir1>
    <dampingFactor>0.43</dampingFactor>
  </gazebo>
  <gazebo reference="sub_wheel_rl_15">
    <mu>44</mu>
    <mu2>2</mu2>
    <fdir1>0 0 0</fdir1>
    <dampingFactor>0.43</dampingFactor>
  </gazebo>
  <gazebo reference="sub_wheel_rr_15">
    <mu>44</mu>
    <mu2>2</mu2>
    <fdir1>0 0 0</fdir1>
    <dampingFactor>0.43</dampingFactor>
  </gazebo>
  <gazebo reference="sub_wheel_fl_16">
    <mu>44</mu>
    <mu2>2</mu2>
    <fdir1>0 0 0</fdir1>
    <dampingFactor>0.43</dampingFactor>
  </gazebo>
  <gazebo reference="sub_wheel_fr_16">
    <mu>44</mu>
    <mu2>2</mu2>
    <fdir1>0 0 0</fdir1>
    <dampingFactor>0.43</dampingFactor>
  </gazebo>
  <gazebo reference="sub_wheel_rl_16">
    <mu>44</mu>
    <mu2>2</mu2>
    <fdir1>0 0 0</fdir1>
    <dampingFactor>0.43</dampingFactor>
  </gazebo>
  <gazebo reference="sub_wheel_rr_16">
    <mu>44</mu>
    <mu2>2</mu2>
    <fdir1>0 0 0</fdir1>
    <dampingFactor>0.43</dampingFactor>
  </gazebo>
  <gazebo reference="sub_wheel_fl_17">
    <mu>44</mu>
    <mu2>2</mu2>
    <fdir1>0 0 0</fdir1>
    <dampingFactor>0.43</dampingFactor>
  </gazebo>
  <gazebo reference="sub_wheel_fr_17">
    <mu>44</mu>
    <mu2>2</mu2>
    <fdir1>0 0 0</fdir1>
    <dampingFactor>0.43</dampingFactor>
  </gazebo>
  <gazebo reference="sub_wheel_rl_17">
    <mu>44</mu>
    <mu2>2</mu2>
    <fdir1>0 0 0</fdir1>
    <dampingFactor>0.43</dampingFactor>
  </gazebo>
  <gazebo reference="sub_wheel_rr_17">
    <mu>44</mu>
    <mu2>2</mu2>
    <fdir1>0 0 0</fdir1>
    <dampingFactor>0.43</dampingFactor>
  </gazebo>
  <gazebo reference="sub_wheel_fl_18">
    <mu>44</mu>
    <mu2>2</mu2>
    <fdir1>0 0 0</fdir1>
    <dampingFactor>0.43</dampingFactor>
  </gazebo>
  <gazebo reference="sub_wheel_fr_18">
    <mu>44</mu>
    <mu2>2</mu2>
    <fdir1>0 0 0</fdir1>
    <dampingFactor>0.43</dampingFactor>
  </gazebo>
  <gazebo reference="sub_wheel_rl_18">
    <mu>44</mu>
    <mu2>2</mu2>
    <fdir1>0 0 0</fdir1>
    <dampingFactor>0.43</dampingFactor>
  </gazebo>
  <gazebo reference="sub_wheel_rr_18">
    <mu>44</mu>
    <mu2>2</mu2>
    <fdir1>0 0 0</fdir1>
    <dampingFactor>0.43</dampingFactor>
  </gazebo>
  <gazebo reference="sub_wheel_fl_19">
    <mu>44</mu>
    <mu2>2</mu2>
    <fdir1>0 0 0</fdir1>
    <dampingFactor>0.43</dampingFactor>
  </gazebo>
  <gazebo reference="sub_wheel_fr_19">
    <mu>44</mu>
    <mu2>2</mu2>
    <fdir1>0 0 0</fdir1>
    <dampingFactor>0.43</dampingFactor>
  </gazebo>
  <gazebo reference="sub_wheel_rl_19">
    <mu>44</mu>
    <mu2>2</mu2>
    <fdir1>0 0 0</fdir1>
    <dampingFactor>0.43</dampingFactor>
  </gazebo>
  <gazebo reference="sub_wheel_rr_19">
    <mu>44</mu>
    <mu2>2</mu2>
    <fdir1>0 0 0</fdir1>
    <dampingFactor>0.43</dampingFactor>
  </gazebo>
  <gazebo reference="sub_wheel_fl_20">
    <mu>44</mu>
    <mu2>2</mu2>
    <fdir1>0 0 0</fdir1>
    <dampingFactor>0.43</dampingFactor>
  </gazebo>
  <gazebo reference="sub_wheel_fr_20">
    <mu>44</mu>
    <mu2>2</mu2>
    <fdir1>0 0 0</fdir1>
    <dampingFactor>0.43</dampingFactor>
  </gazebo>
  <gazebo reference="sub_wheel_rl_20">
    <mu>44</mu>
    <mu2>2</mu2>
    <fdir1>0 0 0</fdir1>
    <dampingFactor>0.43</dampingFactor>
  </gazebo>
  <gazebo reference="sub_wheel_rr_20">
    <mu>44</mu>
    <mu2>2</mu2>
    <fdir1>0 0 0</fdir1>
    <dampingFactor>0.43</dampingFactor>
  </gazebo>
  <gazebo reference="wheel_fl">
    <dampingFactor>0.42</dampingFactor>
  </gazebo>
  <gazebo reference="wheel_fr">
    <dampingFactor>0.42</dampingFactor>
  </gazebo>
  <gazebo reference="wheel_rl">
    <dampingFactor>0.42</dampingFactor>
  </gazebo>
  <gazebo reference="wheel_rr">
    <dampingFactor>0.42</dampingFactor>
  </gazebo>
  <gazebo reference="base_wheel_fl">
  </gazebo>
  <gazebo reference="base_wheel_fr">
  </gazebo>
  <gazebo reference="base_wheel_rl">
  </gazebo>
  <gazebo reference="base_wheel_rr">
  </gazebo>
  <material name="black">
    <color rgba="0.0 0.0 0.0 1.0"/>
  </material>
  <material name="blue">
    <color rgba="0.0 0.0 0.8 1.0"/>
  </material>
  <material name="green">
    <color rgba="0.0 0.8 0.0 1.0"/>
  </material>
  <material name="grey">
    <color rgba="0.2 0.2 0.2 1.0"/>
  </material>
  <material name="orange">
    <color rgba="1.0 0.423529411765 0.0392156862745 1.0"/>
  </material>
  <material name="brown">
    <color rgba="0.870588235294 0.811764705882 0.764705882353 1.0"/>
  </material>
  <material name="red">
    <color rgba="0.8 0.0 0.0 1.0"/>
  </material>
  <material name="white">
    <color rgba="1.0 1.0 1.0 1.0"/>
  </material>
  <material name="aluminium">
    <color rgba="0.811764705882 0.81568627451 0.807843137255 1.0"/>
  </material>
  <link name="base_link">
  </link>
  <link name="base_plate">
    <inertial>
      <origin rpy="0 0 0" xyz="0 0 0.0445"/>
      <mass value="2.50"/>
      <inertia ixx="0.008896" ixy="0" ixz="0" iyy="0.008896" iyz="0" izz="0.009031"/>
    </inertial>
    <!--
   <visual>
     <origin xyz="0 0 0" rpy="0 0 -1.5707"/>
     <geometry>
       <mesh filename="package://ssl_robot_description/meshes/HBG-Roboter-now.stl"/>
       <cylinder radius="${base_radius}" length="${base_height}"/>
     </geometry>
   </visual>
-->
    <!--
   <collision>
     <origin xyz="0 0 ${base_height/2+ground_clearance}" rpy="0 0 0"/>
     <geometry>
       <cylinder radius="${base_radius}" length="${base_height}"/>
     </geometry>
   </collision>
-->
  </link>
  <joint name="base_joint" type="fixed">
    <parent link="base_link"/>
    <child link="base_plate"/>
    <axis xyz="1 0 0"/>
    <origin rpy="0 0 0" xyz="0 0 0.1"/>
  </joint>
  <link name="wheel_fr">
    <inertial>
      <origin rpy="0 1.5707 0" xyz="0.007 0 0"/>
      <mass value="0.05"/>
      <inertia ixx="0.000010" ixy="0" ixz="0" iyy="0.000010" iyz="0" izz="0.000018"/>
    </inertial>
    <!--
      <visual name="wheel-visual" >
        <origin xyz="0 0 0" rpy="0 1.5707 0" />
        <geometry>
          <mesh filename="package://ssl_robot_description/meshes/UBG-Rad.stl"/>
          <cylinder radius="${wheel_radius}" length="${wheel_thickness}" />
        </geometry>
      </visual>
-->
    <!--
      <collision name="wheel">
        <origin xyz="0.005 0 0" rpy="0 1.5707 0" />
        <geometry>
          <cylinder radius="${wheel_radius}" length="${wheel_thickness}" />
        </geometry>
      </collision>
-->
  </link>
  <!--
    <link name="motor_${suffix}">
      <inertial>
        <origin xyz="${robot_wheel_radius-wheel_thickness-0.005} 0 ${wheel_radius}" rpy="0 0 0" />
        <mass value="0.10" />
        <inertia ixx="0.000042" ixy="0" ixz="0" iyy="0.000022" iyz="0" izz="0.000022" />
      </inertial>
      <visual>
        <origin xyz="${robot_wheel_radius-wheel_thickness-0.0005} 0 ${wheel_radius}" rpy="0 0 0" />
        <geometry>
          <box size="0.001 ${wheel_radius*2} ${wheel_radius*2}" />
        </geometry>
      </visual>
    </link>
-->
  <joint name="base_wheel_fr" type="continuous">
    <parent link="base_plate"/>
    <child link="wheel_fr"/>
    <axis xyz="1 0 0"/>
    <!--
      <origin xyz="${robot_wheel_radius} 0 ${wheel_radius-ground_clearance}" rpy="0 0 ${rotation}" />
-->
    <origin rpy="0 0 -1.0472" xyz="0.0375 -0.06495 0.025"/>
    <dynamics damping="0.0" friction="0.01"/>
  </joint>
  <!--
    <joint name="base_motor_${suffix}" type="revolute">
      <parent link="${parent}" />
      <child link="motor_${suffix}" />
      <axis xyz="0 0 1" />
      <limit effort="30" velocity="1.0" lower="${rotation}" upper="${rotation}" />
      <origin xyz="0 0 0" 
              rpy="0 0 0" />
    </joint>
-->
  <link name="sub_wheel_fr_1">
    <inertial>
      <origin rpy="0 0 0" xyz="0 0 0"/>
      <mass value="0.001"/>
      <inertia ixx="0.00000001" ixy="0" ixz="0" iyy="0.00000001" iyz="0" izz="0.00000001"/>
    </inertial>
    <visual name="wheel-visual">
      <origin rpy="0 0 0" xyz="0 0 0"/>
      <geometry>
        <cylinder length="0.0025" radius="0.0065"/>
      </geometry>
    </visual>
    <collision name="wheel">
      <origin rpy="0 0 0" xyz="0 0 0"/>
      <geometry>
        <cylinder length="0.0025" radius="0.0065"/>
      </geometry>
    </collision>
  </link>
  <joint name="wheel_subwheel_fr_1" type="continuous">
    <parent link="wheel_fr"/>
    <child link="sub_wheel_fr_1"/>
    <axis xyz="0 0 1"/>
    <origin rpy="0.0 0 0" xyz="0.007 0.022 0.0"/>
    <dynamics damping="0.0" friction="42"/>
    <!--
      <limit effort="30" velocity="1" />
-->
  </joint>
  <link name="sub_wheel_fr_2">
    <inertial>
      <origin rpy="0 0 0" xyz="0 0 0"/>
      <mass value="0.001"/>
      <inertia ixx="0.00000001" ixy="0" ixz="0" iyy="0.00000001" iyz="0" izz="0.00000001"/>
    </inertial>
    <visual name="wheel-visual">
      <origin rpy="0 0 0" xyz="0 0 0"/>
      <geometry>
        <cylinder length="0.0025" radius="0.0065"/>
      </geometry>
    </visual>
    <collision name="wheel">
      <origin rpy="0 0 0" xyz="0 0 0"/>
      <geometry>
        <cylinder length="0.0025" radius="0.0065"/>
      </geometry>
    </collision>
  </link>
  <joint name="wheel_subwheel_fr_2" type="continuous">
    <parent link="wheel_fr"/>
    <child link="sub_wheel_fr_2"/>
    <axis xyz="0 0 1"/>
    <origin rpy="0.314159 0 0" xyz="0.007 0.020923254 0.006798374"/>
    <dynamics damping="0.0" friction="42"/>
    <!--
      <limit effort="30" velocity="1" />
-->
  </joint>
  <link name="sub_wheel_fr_3">
    <inertial>
      <origin rpy="0 0 0" xyz="0 0 0"/>
      <mass value="0.001"/>
      <inertia ixx="0.00000001" ixy="0" ixz="0" iyy="0.00000001" iyz="0" izz="0.00000001"/>
    </inertial>
    <visual name="wheel-visual">
      <origin rpy="0 0 0" xyz="0 0 0"/>
      <geometry>
        <cylinder length="0.0025" radius="0.0065"/>
      </geometry>
    </visual>
    <collision name="wheel">
      <origin rpy="0 0 0" xyz="0 0 0"/>
      <geometry>
        <cylinder length="0.0025" radius="0.0065"/>
      </geometry>
    </collision>
  </link>
  <joint name="wheel_subwheel_fr_3" type="continuous">
    <parent link="wheel_fr"/>
    <child link="sub_wheel_fr_3"/>
    <axis xyz="0 0 1"/>
    <origin rpy="0.628319 0 0" xyz="0.007 0.017798374 0.01293127"/>
    <dynamics damping="0.0" friction="42"/>
    <!--
      <limit effort="30" velocity="1" />
-->
  </joint>
  <link name="sub_wheel_fr_4">
    <inertial>
      <origin rpy="0 0 0" xyz="0 0 0"/>
      <mass value="0.001"/>
      <inertia ixx="0.00000001" ixy="0" ixz="0" iyy="0.00000001" iyz="0" izz="0.00000001"/>
    </inertial>
    <visual name="wheel-visual">
      <origin rpy="0 0 0" xyz="0 0 0"/>
      <geometry>
        <cylinder length="0.0025" radius="0.0065"/>
      </geometry>
    </visual>
    <collision name="wheel">
      <origin rpy="0 0 0" xyz="0 0 0"/>
      <geometry>
        <cylinder length="0.0025" radius="0.0065"/>
      </geometry>
    </collision>
  </link>
  <joint name="wheel_subwheel_fr_4" type="continuous">
    <parent link="wheel_fr"/>
    <child link="sub_wheel_fr_4"/>
    <axis xyz="0 0 1"/>
    <origin rpy="0.942478 0 0" xyz="0.007 0.01293127 0.017798374"/>
    <dynamics damping="0.0" friction="42"/>
    <!--
      <limit effort="30" velocity="1" />
-->
  </joint>
  <link name="sub_wheel_fr_5">
    <inertial>
      <origin rpy="0 0 0" xyz="0 0 0"/>
      <mass value="0.001"/>
      <inertia ixx="0.00000001" ixy="0" ixz="0" iyy="0.00000001" iyz="0" izz="0.00000001"/>
    </inertial>
    <visual name="wheel-visual">
      <origin rpy="0 0 0" xyz="0 0 0"/>
      <geometry>
        <cylinder length="0.0025" radius="0.0065"/>
      </geometry>
    </visual>
    <collision name="wheel">
      <origin rpy="0 0 0" xyz="0 0 0"/>
      <geometry>
        <cylinder length="0.0025" radius="0.0065"/>
      </geometry>
    </collision>
  </link>
  <joint name="wheel_subwheel_fr_5" type="continuous">
    <parent link="wheel_fr"/>
    <child link="sub_wheel_fr_5"/>
    <axis xyz="0 0 1"/>
    <origin rpy="1.256637 0 0" xyz="0.007 0.006798374 0.020923254"/>
    <dynamics damping="0.0" friction="42"/>
    <!--
      <limit effort="30" velocity="1" />
-->
  </joint>
  <link name="sub_wheel_fr_6">
    <inertial>
      <origin rpy="0 0 0" xyz="0 0 0"/>
      <mass value="0.001"/>
      <inertia ixx="0.00000001" ixy="0" ixz="0" iyy="0.00000001" iyz="0" izz="0.00000001"/>
    </inertial>
    <visual name="wheel-visual">
      <origin rpy="0 0 0" xyz="0 0 0"/>
      <geometry>
        <cylinder length="0.0025" radius="0.0065"/>
      </geometry>
    </visual>
    <collision name="wheel">
      <origin rpy="0 0 0" xyz="0 0 0"/>
      <geometry>
        <cylinder length="0.0025" radius="0.0065"/>
      </geometry>
    </collision>
  </link>
  <joint name="wheel_subwheel_fr_6" type="continuous">
    <parent link="wheel_fr"/>
    <child link="sub_wheel_fr_6"/>
    <axis xyz="0 0 1"/>
    <origin rpy="1.570796 0 0" xyz="0.007 0.0 0.022"/>
    <dynamics damping="0.0" friction="42"/>
    <!--
      <limit effort="30" velocity="1" />
-->
  </joint>
  <link name="sub_wheel_fr_7">
    <inertial>
      <origin rpy="0 0 0" xyz="0 0 0"/>
      <mass value="0.001"/>
      <inertia ixx="0.00000001" ixy="0" ixz="0" iyy="0.00000001" iyz="0" izz="0.00000001"/>
    </inertial>
    <visual name="wheel-visual">
      <origin rpy="0 0 0" xyz="0 0 0"/>
      <geometry>
        <cylinder length="0.0025" radius="0.0065"/>
      </geometry>
    </visual>
    <collision name="wheel">
      <origin rpy="0 0 0" xyz="0 0 0"/>
      <geometry>
        <cylinder length="0.0025" radius="0.0065"/>
      </geometry>
    </collision>
  </link>
  <joint name="wheel_subwheel_fr_7" type="continuous">
    <parent link="wheel_fr"/>
    <child link="sub_wheel_fr_7"/>
    <axis xyz="0 0 1"/>
    <origin rpy="1.884956 0 0" xyz="0.007 -0.006798374 0.020923254"/>
    <dynamics damping="0.0" friction="42"/>
    <!--
      <limit effort="30" velocity="1" />
-->
  </joint>
  <link name="sub_wheel_fr_8">
    <inertial>
      <origin rpy="0 0 0" xyz="0 0 0"/>
      <mass value="0.001"/>
      <inertia ixx="0.00000001" ixy="0" ixz="0" iyy="0.00000001" iyz="0" izz="0.00000001"/>
    </inertial>
    <visual name="wheel-visual">
      <origin rpy="0 0 0" xyz="0 0 0"/>
      <geometry>
        <cylinder length="0.0025" radius="0.0065"/>
      </geometry>
    </visual>
    <collision name="wheel">
      <origin rpy="0 0 0" xyz="0 0 0"/>
      <geometry>
        <cylinder length="0.0025" radius="0.0065"/>
      </geometry>
    </collision>
  </link>
  <joint name="wheel_subwheel_fr_8" type="continuous">
    <parent link="wheel_fr"/>
    <child link="sub_wheel_fr_8"/>
    <axis xyz="0 0 1"/>
    <origin rpy="2.199115 0 0" xyz="0.007 -0.01293127 0.017798374"/>
    <dynamics damping="0.0" friction="42"/>
    <!--
      <limit effort="30" velocity="1" />
-->
  </joint>
  <link name="sub_wheel_fr_9">
    <inertial>
      <origin rpy="0 0 0" xyz="0 0 0"/>
      <mass value="0.001"/>
      <inertia ixx="0.00000001" ixy="0" ixz="0" iyy="0.00000001" iyz="0" izz="0.00000001"/>
    </inertial>
    <visual name="wheel-visual">
      <origin rpy="0 0 0" xyz="0 0 0"/>
      <geometry>
        <cylinder length="0.0025" radius="0.0065"/>
      </geometry>
    </visual>
    <collision name="wheel">
      <origin rpy="0 0 0" xyz="0 0 0"/>
      <geometry>
        <cylinder length="0.0025" radius="0.0065"/>
      </geometry>
    </collision>
  </link>
  <joint name="wheel_subwheel_fr_9" type="continuous">
    <parent link="wheel_fr"/>
    <child link="sub_wheel_fr_9"/>
    <axis xyz="0 0 1"/>
    <origin rpy="2.513274 0 0" xyz="0.007 -0.017798374 0.01293127"/>
    <dynamics damping="0.0" friction="42"/>
    <!--
      <limit effort="30" velocity="1" />
-->
  </joint>
  <link name="sub_wheel_fr_10">
    <inertial>
      <origin rpy="0 0 0" xyz="0 0 0"/>
      <mass value="0.001"/>
      <inertia ixx="0.00000001" ixy="0" ixz="0" iyy="0.00000001" iyz="0" izz="0.00000001"/>
    </inertial>
    <visual name="wheel-visual">
      <origin rpy="0 0 0" xyz="0 0 0"/>
      <geometry>
        <cylinder length="0.0025" radius="0.0065"/>
      </geometry>
    </visual>
    <collision name="wheel">
      <origin rpy="0 0 0" xyz="0 0 0"/>
      <geometry>
        <cylinder length="0.0025" radius="0.0065"/>
      </geometry>
    </collision>
  </link>
  <joint name="wheel_subwheel_fr_10" type="continuous">
    <parent link="wheel_fr"/>
    <child link="sub_wheel_fr_10"/>
    <axis xyz="0 0 1"/>
    <origin rpy="2.827433 0 0" xyz="0.007 -0.020923254 0.006798374"/>
    <dynamics damping="0.0" friction="42"/>
    <!--
      <limit effort="30" velocity="1" />
-->
  </joint>
  <link name="sub_wheel_fr_11">
    <inertial>
      <origin rpy="0 0 0" xyz="0 0 0"/>
      <mass value="0.001"/>
      <inertia ixx="0.00000001" ixy="0" ixz="0" iyy="0.00000001" iyz="0" izz="0.00000001"/>
    </inertial>
    <visual name="wheel-visual">
      <origin rpy="0 0 0" xyz="0 0 0"/>
      <geometry>
        <cylinder length="0.0025" radius="0.0065"/>
      </geometry>
    </visual>
    <collision name="wheel">
      <origin rpy="0 0 0" xyz="0 0 0"/>
      <geometry>
        <cylinder length="0.0025" radius="0.0065"/>
      </geometry>
    </collision>
  </link>
  <joint name="wheel_subwheel_fr_11" type="continuous">
    <parent link="wheel_fr"/>
    <child link="sub_wheel_fr_11"/>
    <axis xyz="0 0 1"/>
    <origin rpy="3.141593 0 0" xyz="0.007 -0.022 0.0"/>
    <dynamics damping="0.0" friction="42"/>
    <!--
      <limit effort="30" velocity="1" />
-->
  </joint>
  <link name="sub_wheel_fr_12">
    <inertial>
      <origin rpy="0 0 0" xyz="0 0 0"/>
      <mass value="0.001"/>
      <inertia ixx="0.00000001" ixy="0" ixz="0" iyy="0.00000001" iyz="0" izz="0.00000001"/>
    </inertial>
    <visual name="wheel-visual">
      <origin rpy="0 0 0" xyz="0 0 0"/>
      <geometry>
        <cylinder length="0.0025" radius="0.0065"/>
      </geometry>
    </visual>
    <collision name="wheel">
      <origin rpy="0 0 0" xyz="0 0 0"/>
      <geometry>
        <cylinder length="0.0025" radius="0.0065"/>
      </geometry>
    </collision>
  </link>
  <joint name="wheel_subwheel_fr_12" type="continuous">
    <parent link="wheel_fr"/>
    <child link="sub_wheel_fr_12"/>
    <axis xyz="0 0 1"/>
    <origin rpy="3.455752 0 0" xyz="0.007 -0.020923254 -0.006798374"/>
    <dynamics damping="0.0" friction="42"/>
    <!--
      <limit effort="30" velocity="1" />
-->
  </joint>
  <link name="sub_wheel_fr_13">
    <inertial>
      <origin rpy="0 0 0" xyz="0 0 0"/>
      <mass value="0.001"/>
      <inertia ixx="0.00000001" ixy="0" ixz="0" iyy="0.00000001" iyz="0" izz="0.00000001"/>
    </inertial>
    <visual name="wheel-visual">
      <origin rpy="0 0 0" xyz="0 0 0"/>
      <geometry>
        <cylinder length="0.0025" radius="0.0065"/>
      </geometry>
    </visual>
    <collision name="wheel">
      <origin rpy="0 0 0" xyz="0 0 0"/>
      <geometry>
        <cylinder length="0.0025" radius="0.0065"/>
      </geometry>
    </collision>
  </link>
  <joint name="wheel_subwheel_fr_13" type="continuous">
    <parent link="wheel_fr"/>
    <child link="sub_wheel_fr_13"/>
    <axis xyz="0 0 1"/>
    <origin rpy="3.769911 0 0" xyz="0.007 -0.017798374 -0.01293127"/>
    <dynamics damping="0.0" friction="42"/>
    <!--
      <limit effort="30" velocity="1" />
-->
  </joint>
  <link name="sub_wheel_fr_14">
    <inertial>
      <origin rpy="0 0 0" xyz="0 0 0"/>
      <mass value="0.001"/>
      <inertia ixx="0.00000001" ixy="0" ixz="0" iyy="0.00000001" iyz="0" izz="0.00000001"/>
    </inertial>
    <visual name="wheel-visual">
      <origin rpy="0 0 0" xyz="0 0 0"/>
      <geometry>
        <cylinder length="0.0025" radius="0.0065"/>
      </geometry>
    </visual>
    <collision name="wheel">
      <origin rpy="0 0 0" xyz="0 0 0"/>
      <geometry>
        <cylinder length="0.0025" radius="0.0065"/>
      </geometry>
    </collision>
  </link>
  <joint name="wheel_subwheel_fr_14" type="continuous">
    <parent link="wheel_fr"/>
    <child link="sub_wheel_fr_14"/>
    <axis xyz="0 0 1"/>
    <origin rpy="4.08407 0 0" xyz="0.007 -0.01293127 -0.017798374"/>
    <dynamics damping="0.0" friction="42"/>
    <!--
      <limit effort="30" velocity="1" />
-->
  </joint>
  <link name="sub_wheel_fr_15">
    <inertial>
      <origin rpy="0 0 0" xyz="0 0 0"/>
      <mass value="0.001"/>
      <inertia ixx="0.00000001" ixy="0" ixz="0" iyy="0.00000001" iyz="0" izz="0.00000001"/>
    </inertial>
    <visual name="wheel-visual">
      <origin rpy="0 0 0" xyz="0 0 0"/>
      <geometry>
        <cylinder length="0.0025" radius="0.0065"/>
      </geometry>
    </visual>
    <collision name="wheel">
      <origin rpy="0 0 0" xyz="0 0 0"/>
      <geometry>
        <cylinder length="0.0025" radius="0.0065"/>
      </geometry>
    </collision>
  </link>
  <joint name="wheel_subwheel_fr_15" type="continuous">
    <parent link="wheel_fr"/>
    <child link="sub_wheel_fr_15"/>
    <axis xyz="0 0 1"/>
    <origin rpy="4.39823 0 0" xyz="0.007 -0.006798374 -0.020923254"/>
    <dynamics damping="0.0" friction="42"/>
    <!--
      <limit effort="30" velocity="1" />
-->
  </joint>
  <link name="sub_wheel_fr_16">
    <inertial>
      <origin rpy="0 0 0" xyz="0 0 0"/>
      <mass value="0.001"/>
      <inertia ixx="0.00000001" ixy="0" ixz="0" iyy="0.00000001" iyz="0" izz="0.00000001"/>
    </inertial>
    <visual name="wheel-visual">
      <origin rpy="0 0 0" xyz="0 0 0"/>
      <geometry>
        <cylinder length="0.0025" radius="0.0065"/>
      </geometry>
    </visual>
    <collision name="wheel">
      <origin rpy="0 0 0" xyz="0 0 0"/>
      <geometry>
        <cylinder length="0.0025" radius="0.0065"/>
      </geometry>
    </collision>
  </link>
  <joint name="wheel_subwheel_fr_16" type="continuous">
    <parent link="wheel_fr"/>
    <child link="sub_wheel_fr_16"/>
    <axis xyz="0 0 1"/>
    <origin rpy="4.712389 0 0" xyz="0.007 -0.0 -0.022"/>
    <dynamics damping="0.0" friction="42"/>
    <!--
      <limit effort="30" velocity="1" />
-->
  </joint>
  <link name="sub_wheel_fr_17">
    <inertial>
      <origin rpy="0 0 0" xyz="0 0 0"/>
      <mass value="0.001"/>
      <inertia ixx="0.00000001" ixy="0" ixz="0" iyy="0.00000001" iyz="0" izz="0.00000001"/>
    </inertial>
    <visual name="wheel-visual">
      <origin rpy="0 0 0" xyz="0 0 0"/>
      <geometry>
        <cylinder length="0.0025" radius="0.0065"/>
      </geometry>
    </visual>
    <collision name="wheel">
      <origin rpy="0 0 0" xyz="0 0 0"/>
      <geometry>
        <cylinder length="0.0025" radius="0.0065"/>
      </geometry>
    </collision>
  </link>
  <joint name="wheel_subwheel_fr_17" type="continuous">
    <parent link="wheel_fr"/>
    <child link="sub_wheel_fr_17"/>
    <axis xyz="0 0 1"/>
    <origin rpy="5.026548 0 0" xyz="0.007 0.006798374 -0.020923254"/>
    <dynamics damping="0.0" friction="42"/>
    <!--
      <limit effort="30" velocity="1" />
-->
  </joint>
  <link name="sub_wheel_fr_18">
    <inertial>
      <origin rpy="0 0 0" xyz="0 0 0"/>
      <mass value="0.001"/>
      <inertia ixx="0.00000001" ixy="0" ixz="0" iyy="0.00000001" iyz="0" izz="0.00000001"/>
    </inertial>
    <visual name="wheel-visual">
      <origin rpy="0 0 0" xyz="0 0 0"/>
      <geometry>
        <cylinder length="0.0025" radius="0.0065"/>
      </geometry>
    </visual>
    <collision name="wheel">
      <origin rpy="0 0 0" xyz="0 0 0"/>
      <geometry>
        <cylinder length="0.0025" radius="0.0065"/>
      </geometry>
    </collision>
  </link>
  <joint name="wheel_subwheel_fr_18" type="continuous">
    <parent link="wheel_fr"/>
    <child link="sub_wheel_fr_18"/>
    <axis xyz="0 0 1"/>
    <origin rpy="5.340708 0 0" xyz="0.007 0.01293127 -0.017798374"/>
    <dynamics damping="0.0" friction="42"/>
    <!--
      <limit effort="30" velocity="1" />
-->
  </joint>
  <link name="sub_wheel_fr_19">
    <inertial>
      <origin rpy="0 0 0" xyz="0 0 0"/>
      <mass value="0.001"/>
      <inertia ixx="0.00000001" ixy="0" ixz="0" iyy="0.00000001" iyz="0" izz="0.00000001"/>
    </inertial>
    <visual name="wheel-visual">
      <origin rpy="0 0 0" xyz="0 0 0"/>
      <geometry>
        <cylinder length="0.0025" radius="0.0065"/>
      </geometry>
    </visual>
    <collision name="wheel">
      <origin rpy="0 0 0" xyz="0 0 0"/>
      <geometry>
        <cylinder length="0.0025" radius="0.0065"/>
      </geometry>
    </collision>
  </link>
  <joint name="wheel_subwheel_fr_19" type="continuous">
    <parent link="wheel_fr"/>
    <child link="sub_wheel_fr_19"/>
    <axis xyz="0 0 1"/>
    <origin rpy="5.654867 0 0" xyz="0.007 0.017798374 -0.01293127"/>
    <dynamics damping="0.0" friction="42"/>
    <!--
      <limit effort="30" velocity="1" />
-->
  </joint>
  <link name="sub_wheel_fr_20">
    <inertial>
      <origin rpy="0 0 0" xyz="0 0 0"/>
      <mass value="0.001"/>
      <inertia ixx="0.00000001" ixy="0" ixz="0" iyy="0.00000001" iyz="0" izz="0.00000001"/>
    </inertial>
    <visual name="wheel-visual">
      <origin rpy="0 0 0" xyz="0 0 0"/>
      <geometry>
        <cylinder length="0.0025" radius="0.0065"/>
      </geometry>
    </visual>
    <collision name="wheel">
      <origin rpy="0 0 0" xyz="0 0 0"/>
      <geometry>
        <cylinder length="0.0025" radius="0.0065"/>
      </geometry>
    </collision>
  </link>
  <joint name="wheel_subwheel_fr_20" type="continuous">
    <parent link="wheel_fr"/>
    <child link="sub_wheel_fr_20"/>
    <axis xyz="0 0 1"/>
    <origin rpy="5.969026 0 0" xyz="0.007 0.020923254 -0.006798374"/>
    <dynamics damping="0.0" friction="42"/>
    <!--
      <limit effort="30" velocity="1" />
-->
  </joint>
  <transmission name="tran_fr">
    <type>transmission_interface/SimpleTransmission</type>
    <joint name="base_wheel_fr">
      <hardwareInterface>EffortJointInterface</hardwareInterface>
    </joint>
    <actuator name="wheel_fr">
      <hardwareInterface>EffortJointInterface</hardwareInterface>
      <mechanicalReduction>1</mechanicalReduction>
    </actuator>
  </transmission>
  <link name="wheel_fl">
    <inertial>
      <origin rpy="0 1.5707 0" xyz="0.007 0 0"/>
      <mass value="0.05"/>
      <inertia ixx="0.000010" ixy="0" ixz="0" iyy="0.000010" iyz="0" izz="0.000018"/>
    </inertial>
    <!--
      <visual name="wheel-visual" >
        <origin xyz="0 0 0" rpy="0 1.5707 0" />
        <geometry>
          <mesh filename="package://ssl_robot_description/meshes/UBG-Rad.stl"/>
          <cylinder radius="${wheel_radius}" length="${wheel_thickness}" />
        </geometry>
      </visual>
-->
    <!--
      <collision name="wheel">
        <origin xyz="0.005 0 0" rpy="0 1.5707 0" />
        <geometry>
          <cylinder radius="${wheel_radius}" length="${wheel_thickness}" />
        </geometry>
      </collision>
-->
  </link>
  <!--
    <link name="motor_${suffix}">
      <inertial>
        <origin xyz="${robot_wheel_radius-wheel_thickness-0.005} 0 ${wheel_radius}" rpy="0 0 0" />
        <mass value="0.10" />
        <inertia ixx="0.000042" ixy="0" ixz="0" iyy="0.000022" iyz="0" izz="0.000022" />
      </inertial>
      <visual>
        <origin xyz="${robot_wheel_radius-wheel_thickness-0.0005} 0 ${wheel_radius}" rpy="0 0 0" />
        <geometry>
          <box size="0.001 ${wheel_radius*2} ${wheel_radius*2}" />
        </geometry>
      </visual>
    </link>
-->
  <joint name="base_wheel_fl" type="continuous">
    <parent link="base_plate"/>
    <child link="wheel_fl"/>
    <axis xyz="1 0 0"/>
    <!--
      <origin xyz="${robot_wheel_radius} 0 ${wheel_radius-ground_clearance}" rpy="0 0 ${rotation}" />
-->
    <origin rpy="0 0 1.0472" xyz="0.0375 0.06495 0.025"/>
    <dynamics damping="0.0" friction="0.01"/>
  </joint>
  <!--
    <joint name="base_motor_${suffix}" type="revolute">
      <parent link="${parent}" />
      <child link="motor_${suffix}" />
      <axis xyz="0 0 1" />
      <limit effort="30" velocity="1.0" lower="${rotation}" upper="${rotation}" />
      <origin xyz="0 0 0" 
              rpy="0 0 0" />
    </joint>
-->
  <link name="sub_wheel_fl_1">
    <inertial>
      <origin rpy="0 0 0" xyz="0 0 0"/>
      <mass value="0.001"/>
      <inertia ixx="0.00000001" ixy="0" ixz="0" iyy="0.00000001" iyz="0" izz="0.00000001"/>
    </inertial>
    <visual name="wheel-visual">
      <origin rpy="0 0 0" xyz="0 0 0"/>
      <geometry>
        <cylinder length="0.0025" radius="0.0065"/>
      </geometry>
    </visual>
    <collision name="wheel">
      <origin rpy="0 0 0" xyz="0 0 0"/>
      <geometry>
        <cylinder length="0.0025" radius="0.0065"/>
      </geometry>
    </collision>
  </link>
  <joint name="wheel_subwheel_fl_1" type="continuous">
    <parent link="wheel_fl"/>
    <child link="sub_wheel_fl_1"/>
    <axis xyz="0 0 1"/>
    <origin rpy="0.0 0 0" xyz="0.007 0.022 0.0"/>
    <dynamics damping="0.0" friction="42"/>
    <!--
      <limit effort="30" velocity="1" />
-->
  </joint>
  <link name="sub_wheel_fl_2">
    <inertial>
      <origin rpy="0 0 0" xyz="0 0 0"/>
      <mass value="0.001"/>
      <inertia ixx="0.00000001" ixy="0" ixz="0" iyy="0.00000001" iyz="0" izz="0.00000001"/>
    </inertial>
    <visual name="wheel-visual">
      <origin rpy="0 0 0" xyz="0 0 0"/>
      <geometry>
        <cylinder length="0.0025" radius="0.0065"/>
      </geometry>
    </visual>
    <collision name="wheel">
      <origin rpy="0 0 0" xyz="0 0 0"/>
      <geometry>
        <cylinder length="0.0025" radius="0.0065"/>
      </geometry>
    </collision>
  </link>
  <joint name="wheel_subwheel_fl_2" type="continuous">
    <parent link="wheel_fl"/>
    <child link="sub_wheel_fl_2"/>
    <axis xyz="0 0 1"/>
    <origin rpy="0.314159 0 0" xyz="0.007 0.020923254 0.006798374"/>
    <dynamics damping="0.0" friction="42"/>
    <!--
      <limit effort="30" velocity="1" />
-->
  </joint>
  <link name="sub_wheel_fl_3">
    <inertial>
      <origin rpy="0 0 0" xyz="0 0 0"/>
      <mass value="0.001"/>
      <inertia ixx="0.00000001" ixy="0" ixz="0" iyy="0.00000001" iyz="0" izz="0.00000001"/>
    </inertial>
    <visual name="wheel-visual">
      <origin rpy="0 0 0" xyz="0 0 0"/>
      <geometry>
        <cylinder length="0.0025" radius="0.0065"/>
      </geometry>
    </visual>
    <collision name="wheel">
      <origin rpy="0 0 0" xyz="0 0 0"/>
      <geometry>
        <cylinder length="0.0025" radius="0.0065"/>
      </geometry>
    </collision>
  </link>
  <joint name="wheel_subwheel_fl_3" type="continuous">
    <parent link="wheel_fl"/>
    <child link="sub_wheel_fl_3"/>
    <axis xyz="0 0 1"/>
    <origin rpy="0.628319 0 0" xyz="0.007 0.017798374 0.01293127"/>
    <dynamics damping="0.0" friction="42"/>
    <!--
      <limit effort="30" velocity="1" />
-->
  </joint>
  <link name="sub_wheel_fl_4">
    <inertial>
      <origin rpy="0 0 0" xyz="0 0 0"/>
      <mass value="0.001"/>
      <inertia ixx="0.00000001" ixy="0" ixz="0" iyy="0.00000001" iyz="0" izz="0.00000001"/>
    </inertial>
    <visual name="wheel-visual">
      <origin rpy="0 0 0" xyz="0 0 0"/>
      <geometry>
        <cylinder length="0.0025" radius="0.0065"/>
      </geometry>
    </visual>
    <collision name="wheel">
      <origin rpy="0 0 0" xyz="0 0 0"/>
      <geometry>
        <cylinder length="0.0025" radius="0.0065"/>
      </geometry>
    </collision>
  </link>
  <joint name="wheel_subwheel_fl_4" type="continuous">
    <parent link="wheel_fl"/>
    <child link="sub_wheel_fl_4"/>
    <axis xyz="0 0 1"/>
    <origin rpy="0.942478 0 0" xyz="0.007 0.01293127 0.017798374"/>
    <dynamics damping="0.0" friction="42"/>
    <!--
      <limit effort="30" velocity="1" />
-->
  </joint>
  <link name="sub_wheel_fl_5">
    <inertial>
      <origin rpy="0 0 0" xyz="0 0 0"/>
      <mass value="0.001"/>
      <inertia ixx="0.00000001" ixy="0" ixz="0" iyy="0.00000001" iyz="0" izz="0.00000001"/>
    </inertial>
    <visual name="wheel-visual">
      <origin rpy="0 0 0" xyz="0 0 0"/>
      <geometry>
        <cylinder length="0.0025" radius="0.0065"/>
      </geometry>
    </visual>
    <collision name="wheel">
      <origin rpy="0 0 0" xyz="0 0 0"/>
      <geometry>
        <cylinder length="0.0025" radius="0.0065"/>
      </geometry>
    </collision>
  </link>
  <joint name="wheel_subwheel_fl_5" type="continuous">
    <parent link="wheel_fl"/>
    <child link="sub_wheel_fl_5"/>
    <axis xyz="0 0 1"/>
    <origin rpy="1.256637 0 0" xyz="0.007 0.006798374 0.020923254"/>
    <dynamics damping="0.0" friction="42"/>
    <!--
      <limit effort="30" velocity="1" />
-->
  </joint>
  <link name="sub_wheel_fl_6">
    <inertial>
      <origin rpy="0 0 0" xyz="0 0 0"/>
      <mass value="0.001"/>
      <inertia ixx="0.00000001" ixy="0" ixz="0" iyy="0.00000001" iyz="0" izz="0.00000001"/>
    </inertial>
    <visual name="wheel-visual">
      <origin rpy="0 0 0" xyz="0 0 0"/>
      <geometry>
        <cylinder length="0.0025" radius="0.0065"/>
      </geometry>
    </visual>
    <collision name="wheel">
      <origin rpy="0 0 0" xyz="0 0 0"/>
      <geometry>
        <cylinder length="0.0025" radius="0.0065"/>
      </geometry>
    </collision>
  </link>
  <joint name="wheel_subwheel_fl_6" type="continuous">
    <parent link="wheel_fl"/>
    <child link="sub_wheel_fl_6"/>
    <axis xyz="0 0 1"/>
    <origin rpy="1.570796 0 0" xyz="0.007 0.0 0.022"/>
    <dynamics damping="0.0" friction="42"/>
    <!--
      <limit effort="30" velocity="1" />
-->
  </joint>
  <link name="sub_wheel_fl_7">
    <inertial>
      <origin rpy="0 0 0" xyz="0 0 0"/>
      <mass value="0.001"/>
      <inertia ixx="0.00000001" ixy="0" ixz="0" iyy="0.00000001" iyz="0" izz="0.00000001"/>
    </inertial>
    <visual name="wheel-visual">
      <origin rpy="0 0 0" xyz="0 0 0"/>
      <geometry>
        <cylinder length="0.0025" radius="0.0065"/>
      </geometry>
    </visual>
    <collision name="wheel">
      <origin rpy="0 0 0" xyz="0 0 0"/>
      <geometry>
        <cylinder length="0.0025" radius="0.0065"/>
      </geometry>
    </collision>
  </link>
  <joint name="wheel_subwheel_fl_7" type="continuous">
    <parent link="wheel_fl"/>
    <child link="sub_wheel_fl_7"/>
    <axis xyz="0 0 1"/>
    <origin rpy="1.884956 0 0" xyz="0.007 -0.006798374 0.020923254"/>
    <dynamics damping="0.0" friction="42"/>
    <!--
      <limit effort="30" velocity="1" />
-->
  </joint>
  <link name="sub_wheel_fl_8">
    <inertial>
      <origin rpy="0 0 0" xyz="0 0 0"/>
      <mass value="0.001"/>
      <inertia ixx="0.00000001" ixy="0" ixz="0" iyy="0.00000001" iyz="0" izz="0.00000001"/>
    </inertial>
    <visual name="wheel-visual">
      <origin rpy="0 0 0" xyz="0 0 0"/>
      <geometry>
        <cylinder length="0.0025" radius="0.0065"/>
      </geometry>
    </visual>
    <collision name="wheel">
      <origin rpy="0 0 0" xyz="0 0 0"/>
      <geometry>
        <cylinder length="0.0025" radius="0.0065"/>
      </geometry>
    </collision>
  </link>
  <joint name="wheel_subwheel_fl_8" type="continuous">
    <parent link="wheel_fl"/>
    <child link="sub_wheel_fl_8"/>
    <axis xyz="0 0 1"/>
    <origin rpy="2.199115 0 0" xyz="0.007 -0.01293127 0.017798374"/>
    <dynamics damping="0.0" friction="42"/>
    <!--
      <limit effort="30" velocity="1" />
-->
  </joint>
  <link name="sub_wheel_fl_9">
    <inertial>
      <origin rpy="0 0 0" xyz="0 0 0"/>
      <mass value="0.001"/>
      <inertia ixx="0.00000001" ixy="0" ixz="0" iyy="0.00000001" iyz="0" izz="0.00000001"/>
    </inertial>
    <visual name="wheel-visual">
      <origin rpy="0 0 0" xyz="0 0 0"/>
      <geometry>
        <cylinder length="0.0025" radius="0.0065"/>
      </geometry>
    </visual>
    <collision name="wheel">
      <origin rpy="0 0 0" xyz="0 0 0"/>
      <geometry>
        <cylinder length="0.0025" radius="0.0065"/>
      </geometry>
    </collision>
  </link>
  <joint name="wheel_subwheel_fl_9" type="continuous">
    <parent link="wheel_fl"/>
    <child link="sub_wheel_fl_9"/>
    <axis xyz="0 0 1"/>
    <origin rpy="2.513274 0 0" xyz="0.007 -0.017798374 0.01293127"/>
    <dynamics damping="0.0" friction="42"/>
    <!--
      <limit effort="30" velocity="1" />
-->
  </joint>
  <link name="sub_wheel_fl_10">
    <inertial>
      <origin rpy="0 0 0" xyz="0 0 0"/>
      <mass value="0.001"/>
      <inertia ixx="0.00000001" ixy="0" ixz="0" iyy="0.00000001" iyz="0" izz="0.00000001"/>
    </inertial>
    <visual name="wheel-visual">
      <origin rpy="0 0 0" xyz="0 0 0"/>
      <geometry>
        <cylinder length="0.0025" radius="0.0065"/>
      </geometry>
    </visual>
    <collision name="wheel">
      <origin rpy="0 0 0" xyz="0 0 0"/>
      <geometry>
        <cylinder length="0.0025" radius="0.0065"/>
      </geometry>
    </collision>
  </link>
  <joint name="wheel_subwheel_fl_10" type="continuous">
    <parent link="wheel_fl"/>
    <child link="sub_wheel_fl_10"/>
    <axis xyz="0 0 1"/>
    <origin rpy="2.827433 0 0" xyz="0.007 -0.020923254 0.006798374"/>
    <dynamics damping="0.0" friction="42"/>
    <!--
      <limit effort="30" velocity="1" />
-->
  </joint>
  <link name="sub_wheel_fl_11">
    <inertial>
      <origin rpy="0 0 0" xyz="0 0 0"/>
      <mass value="0.001"/>
      <inertia ixx="0.00000001" ixy="0" ixz="0" iyy="0.00000001" iyz="0" izz="0.00000001"/>
    </inertial>
    <visual name="wheel-visual">
      <origin rpy="0 0 0" xyz="0 0 0"/>
      <geometry>
        <cylinder length="0.0025" radius="0.0065"/>
      </geometry>
    </visual>
    <collision name="wheel">
      <origin rpy="0 0 0" xyz="0 0 0"/>
      <geometry>
        <cylinder length="0.0025" radius="0.0065"/>
      </geometry>
    </collision>
  </link>
  <joint name="wheel_subwheel_fl_11" type="continuous">
    <parent link="wheel_fl"/>
    <child link="sub_wheel_fl_11"/>
    <axis xyz="0 0 1"/>
    <origin rpy="3.141593 0 0" xyz="0.007 -0.022 0.0"/>
    <dynamics damping="0.0" friction="42"/>
    <!--
      <limit effort="30" velocity="1" />
-->
  </joint>
  <link name="sub_wheel_fl_12">
    <inertial>
      <origin rpy="0 0 0" xyz="0 0 0"/>
      <mass value="0.001"/>
      <inertia ixx="0.00000001" ixy="0" ixz="0" iyy="0.00000001" iyz="0" izz="0.00000001"/>
    </inertial>
    <visual name="wheel-visual">
      <origin rpy="0 0 0" xyz="0 0 0"/>
      <geometry>
        <cylinder length="0.0025" radius="0.0065"/>
      </geometry>
    </visual>
    <collision name="wheel">
      <origin rpy="0 0 0" xyz="0 0 0"/>
      <geometry>
        <cylinder length="0.0025" radius="0.0065"/>
      </geometry>
    </collision>
  </link>
  <joint name="wheel_subwheel_fl_12" type="continuous">
    <parent link="wheel_fl"/>
    <child link="sub_wheel_fl_12"/>
    <axis xyz="0 0 1"/>
    <origin rpy="3.455752 0 0" xyz="0.007 -0.020923254 -0.006798374"/>
    <dynamics damping="0.0" friction="42"/>
    <!--
      <limit effort="30" velocity="1" />
-->
  </joint>
  <link name="sub_wheel_fl_13">
    <inertial>
      <origin rpy="0 0 0" xyz="0 0 0"/>
      <mass value="0.001"/>
      <inertia ixx="0.00000001" ixy="0" ixz="0" iyy="0.00000001" iyz="0" izz="0.00000001"/>
    </inertial>
    <visual name="wheel-visual">
      <origin rpy="0 0 0" xyz="0 0 0"/>
      <geometry>
        <cylinder length="0.0025" radius="0.0065"/>
      </geometry>
    </visual>
    <collision name="wheel">
      <origin rpy="0 0 0" xyz="0 0 0"/>
      <geometry>
        <cylinder length="0.0025" radius="0.0065"/>
      </geometry>
    </collision>
  </link>
  <joint name="wheel_subwheel_fl_13" type="continuous">
    <parent link="wheel_fl"/>
    <child link="sub_wheel_fl_13"/>
    <axis xyz="0 0 1"/>
    <origin rpy="3.769911 0 0" xyz="0.007 -0.017798374 -0.01293127"/>
    <dynamics damping="0.0" friction="42"/>
    <!--
      <limit effort="30" velocity="1" />
-->
  </joint>
  <link name="sub_wheel_fl_14">
    <inertial>
      <origin rpy="0 0 0" xyz="0 0 0"/>
      <mass value="0.001"/>
      <inertia ixx="0.00000001" ixy="0" ixz="0" iyy="0.00000001" iyz="0" izz="0.00000001"/>
    </inertial>
    <visual name="wheel-visual">
      <origin rpy="0 0 0" xyz="0 0 0"/>
      <geometry>
        <cylinder length="0.0025" radius="0.0065"/>
      </geometry>
    </visual>
    <collision name="wheel">
      <origin rpy="0 0 0" xyz="0 0 0"/>
      <geometry>
        <cylinder length="0.0025" radius="0.0065"/>
      </geometry>
    </collision>
  </link>
  <joint name="wheel_subwheel_fl_14" type="continuous">
    <parent link="wheel_fl"/>
    <child link="sub_wheel_fl_14"/>
    <axis xyz="0 0 1"/>
    <origin rpy="4.08407 0 0" xyz="0.007 -0.01293127 -0.017798374"/>
    <dynamics damping="0.0" friction="42"/>
    <!--
      <limit effort="30" velocity="1" />
-->
  </joint>
  <link name="sub_wheel_fl_15">
    <inertial>
      <origin rpy="0 0 0" xyz="0 0 0"/>
      <mass value="0.001"/>
      <inertia ixx="0.00000001" ixy="0" ixz="0" iyy="0.00000001" iyz="0" izz="0.00000001"/>
    </inertial>
    <visual name="wheel-visual">
      <origin rpy="0 0 0" xyz="0 0 0"/>
      <geometry>
        <cylinder length="0.0025" radius="0.0065"/>
      </geometry>
    </visual>
    <collision name="wheel">
      <origin rpy="0 0 0" xyz="0 0 0"/>
      <geometry>
        <cylinder length="0.0025" radius="0.0065"/>
      </geometry>
    </collision>
  </link>
  <joint name="wheel_subwheel_fl_15" type="continuous">
    <parent link="wheel_fl"/>
    <child link="sub_wheel_fl_15"/>
    <axis xyz="0 0 1"/>
    <origin rpy="4.39823 0 0" xyz="0.007 -0.006798374 -0.020923254"/>
    <dynamics damping="0.0" friction="42"/>
    <!--
      <limit effort="30" velocity="1" />
-->
  </joint>
  <link name="sub_wheel_fl_16">
    <inertial>
      <origin rpy="0 0 0" xyz="0 0 0"/>
      <mass value="0.001"/>
      <inertia ixx="0.00000001" ixy="0" ixz="0" iyy="0.00000001" iyz="0" izz="0.00000001"/>
    </inertial>
    <visual name="wheel-visual">
      <origin rpy="0 0 0" xyz="0 0 0"/>
      <geometry>
        <cylinder length="0.0025" radius="0.0065"/>
      </geometry>
    </visual>
    <collision name="wheel">
      <origin rpy="0 0 0" xyz="0 0 0"/>
      <geometry>
        <cylinder length="0.0025" radius="0.0065"/>
      </geometry>
    </collision>
  </link>
  <joint name="wheel_subwheel_fl_16" type="continuous">
    <parent link="wheel_fl"/>
    <child link="sub_wheel_fl_16"/>
    <axis xyz="0 0 1"/>
    <origin rpy="4.712389 0 0" xyz="0.007 -0.0 -0.022"/>
    <dynamics damping="0.0" friction="42"/>
    <!--
      <limit effort="30" velocity="1" />
-->
  </joint>
  <link name="sub_wheel_fl_17">
    <inertial>
      <origin rpy="0 0 0" xyz="0 0 0"/>
      <mass value="0.001"/>
      <inertia ixx="0.00000001" ixy="0" ixz="0" iyy="0.00000001" iyz="0" izz="0.00000001"/>
    </inertial>
    <visual name="wheel-visual">
      <origin rpy="0 0 0" xyz="0 0 0"/>
      <geometry>
        <cylinder length="0.0025" radius="0.0065"/>
      </geometry>
    </visual>
    <collision name="wheel">
      <origin rpy="0 0 0" xyz="0 0 0"/>
      <geometry>
        <cylinder length="0.0025" radius="0.0065"/>
      </geometry>
    </collision>
  </link>
  <joint name="wheel_subwheel_fl_17" type="continuous">
    <parent link="wheel_fl"/>
    <child link="sub_wheel_fl_17"/>
    <axis xyz="0 0 1"/>
    <origin rpy="5.026548 0 0" xyz="0.007 0.006798374 -0.020923254"/>
    <dynamics damping="0.0" friction="42"/>
    <!--
      <limit effort="30" velocity="1" />
-->
  </joint>
  <link name="sub_wheel_fl_18">
    <inertial>
      <origin rpy="0 0 0" xyz="0 0 0"/>
      <mass value="0.001"/>
      <inertia ixx="0.00000001" ixy="0" ixz="0" iyy="0.00000001" iyz="0" izz="0.00000001"/>
    </inertial>
    <visual name="wheel-visual">
      <origin rpy="0 0 0" xyz="0 0 0"/>
      <geometry>
        <cylinder length="0.0025" radius="0.0065"/>
      </geometry>
    </visual>
    <collision name="wheel">
      <origin rpy="0 0 0" xyz="0 0 0"/>
      <geometry>
        <cylinder length="0.0025" radius="0.0065"/>
      </geometry>
    </collision>
  </link>
  <joint name="wheel_subwheel_fl_18" type="continuous">
    <parent link="wheel_fl"/>
    <child link="sub_wheel_fl_18"/>
    <axis xyz="0 0 1"/>
    <origin rpy="5.340708 0 0" xyz="0.007 0.01293127 -0.017798374"/>
    <dynamics damping="0.0" friction="42"/>
    <!--
      <limit effort="30" velocity="1" />
-->
  </joint>
  <link name="sub_wheel_fl_19">
    <inertial>
      <origin rpy="0 0 0" xyz="0 0 0"/>
      <mass value="0.001"/>
      <inertia ixx="0.00000001" ixy="0" ixz="0" iyy="0.00000001" iyz="0" izz="0.00000001"/>
    </inertial>
    <visual name="wheel-visual">
      <origin rpy="0 0 0" xyz="0 0 0"/>
      <geometry>
        <cylinder length="0.0025" radius="0.0065"/>
      </geometry>
    </visual>
    <collision name="wheel">
      <origin rpy="0 0 0" xyz="0 0 0"/>
      <geometry>
        <cylinder length="0.0025" radius="0.0065"/>
      </geometry>
    </collision>
  </link>
  <joint name="wheel_subwheel_fl_19" type="continuous">
    <parent link="wheel_fl"/>
    <child link="sub_wheel_fl_19"/>
    <axis xyz="0 0 1"/>
    <origin rpy="5.654867 0 0" xyz="0.007 0.017798374 -0.01293127"/>
    <dynamics damping="0.0" friction="42"/>
    <!--
      <limit effort="30" velocity="1" />
-->
  </joint>
  <link name="sub_wheel_fl_20">
    <inertial>
      <origin rpy="0 0 0" xyz="0 0 0"/>
      <mass value="0.001"/>
      <inertia ixx="0.00000001" ixy="0" ixz="0" iyy="0.00000001" iyz="0" izz="0.00000001"/>
    </inertial>
    <visual name="wheel-visual">
      <origin rpy="0 0 0" xyz="0 0 0"/>
      <geometry>
        <cylinder length="0.0025" radius="0.0065"/>
      </geometry>
    </visual>
    <collision name="wheel">
      <origin rpy="0 0 0" xyz="0 0 0"/>
      <geometry>
        <cylinder length="0.0025" radius="0.0065"/>
      </geometry>
    </collision>
  </link>
  <joint name="wheel_subwheel_fl_20" type="continuous">
    <parent link="wheel_fl"/>
    <child link="sub_wheel_fl_20"/>
    <axis xyz="0 0 1"/>
    <origin rpy="5.969026 0 0" xyz="0.007 0.020923254 -0.006798374"/>
    <dynamics damping="0.0" friction="42"/>
    <!--
      <limit effort="30" velocity="1" />
-->
  </joint>
  <transmission name="tran_fl">
    <type>transmission_interface/SimpleTransmission</type>
    <joint name="base_wheel_fl">
      <hardwareInterface>EffortJointInterface</hardwareInterface>
    </joint>
    <actuator name="wheel_fl">
      <hardwareInterface>EffortJointInterface</hardwareInterface>
      <mechanicalReduction>1</mechanicalReduction>
    </actuator>
  </transmission>
  <link name="wheel_rl">
    <inertial>
      <origin rpy="0 1.5707 0" xyz="0.007 0 0"/>
      <mass value="0.05"/>
      <inertia ixx="0.000010" ixy="0" ixz="0" iyy="0.000010" iyz="0" izz="0.000018"/>
    </inertial>
    <!--
      <visual name="wheel-visual" >
        <origin xyz="0 0 0" rpy="0 1.5707 0" />
        <geometry>
          <mesh filename="package://ssl_robot_description/meshes/UBG-Rad.stl"/>
          <cylinder radius="${wheel_radius}" length="${wheel_thickness}" />
        </geometry>
      </visual>
-->
    <!--
      <collision name="wheel">
        <origin xyz="0.005 0 0" rpy="0 1.5707 0" />
        <geometry>
          <cylinder radius="${wheel_radius}" length="${wheel_thickness}" />
        </geometry>
      </collision>
-->
  </link>
  <!--
    <link name="motor_${suffix}">
      <inertial>
        <origin xyz="${robot_wheel_radius-wheel_thickness-0.005} 0 ${wheel_radius}" rpy="0 0 0" />
        <mass value="0.10" />
        <inertia ixx="0.000042" ixy="0" ixz="0" iyy="0.000022" iyz="0" izz="0.000022" />
      </inertial>
      <visual>
        <origin xyz="${robot_wheel_radius-wheel_thickness-0.0005} 0 ${wheel_radius}" rpy="0 0 0" />
        <geometry>
          <box size="0.001 ${wheel_radius*2} ${wheel_radius*2}" />
        </geometry>
      </visual>
    </link>
-->
  <joint name="base_wheel_rl" type="continuous">
    <parent link="base_plate"/>
    <child link="wheel_rl"/>
    <axis xyz="1 0 0"/>
    <!--
      <origin xyz="${robot_wheel_radius} 0 ${wheel_radius-ground_clearance}" rpy="0 0 ${rotation}" />
-->
    <origin rpy="0 0 2.3562" xyz="-0.0530325 0.0530325 0.025"/>
    <dynamics damping="0.0" friction="0.01"/>
  </joint>
  <!--
    <joint name="base_motor_${suffix}" type="revolute">
      <parent link="${parent}" />
      <child link="motor_${suffix}" />
      <axis xyz="0 0 1" />
      <limit effort="30" velocity="1.0" lower="${rotation}" upper="${rotation}" />
      <origin xyz="0 0 0" 
              rpy="0 0 0" />
    </joint>
-->
  <link name="sub_wheel_rl_1">
    <inertial>
      <origin rpy="0 0 0" xyz="0 0 0"/>
      <mass value="0.001"/>
      <inertia ixx="0.00000001" ixy="0" ixz="0" iyy="0.00000001" iyz="0" izz="0.00000001"/>
    </inertial>
    <visual name="wheel-visual">
      <origin rpy="0 0 0" xyz="0 0 0"/>
      <geometry>
        <cylinder length="0.0025" radius="0.0065"/>
      </geometry>
    </visual>
    <collision name="wheel">
      <origin rpy="0 0 0" xyz="0 0 0"/>
      <geometry>
        <cylinder length="0.0025" radius="0.0065"/>
      </geometry>
    </collision>
  </link>
  <joint name="wheel_subwheel_rl_1" type="continuous">
    <parent link="wheel_rl"/>
    <child link="sub_wheel_rl_1"/>
    <axis xyz="0 0 1"/>
    <origin rpy="0.0 0 0" xyz="0.007 0.022 0.0"/>
    <dynamics damping="0.0" friction="42"/>
    <!--
      <limit effort="30" velocity="1" />
-->
  </joint>
  <link name="sub_wheel_rl_2">
    <inertial>
      <origin rpy="0 0 0" xyz="0 0 0"/>
      <mass value="0.001"/>
      <inertia ixx="0.00000001" ixy="0" ixz="0" iyy="0.00000001" iyz="0" izz="0.00000001"/>
    </inertial>
    <visual name="wheel-visual">
      <origin rpy="0 0 0" xyz="0 0 0"/>
      <geometry>
        <cylinder length="0.0025" radius="0.0065"/>
      </geometry>
    </visual>
    <collision name="wheel">
      <origin rpy="0 0 0" xyz="0 0 0"/>
      <geometry>
        <cylinder length="0.0025" radius="0.0065"/>
      </geometry>
    </collision>
  </link>
  <joint name="wheel_subwheel_rl_2" type="continuous">
    <parent link="wheel_rl"/>
    <child link="sub_wheel_rl_2"/>
    <axis xyz="0 0 1"/>
    <origin rpy="0.314159 0 0" xyz="0.007 0.020923254 0.006798374"/>
    <dynamics damping="0.0" friction="42"/>
    <!--
      <limit effort="30" velocity="1" />
-->
  </joint>
  <link name="sub_wheel_rl_3">
    <inertial>
      <origin rpy="0 0 0" xyz="0 0 0"/>
      <mass value="0.001"/>
      <inertia ixx="0.00000001" ixy="0" ixz="0" iyy="0.00000001" iyz="0" izz="0.00000001"/>
    </inertial>
    <visual name="wheel-visual">
      <origin rpy="0 0 0" xyz="0 0 0"/>
      <geometry>
        <cylinder length="0.0025" radius="0.0065"/>
      </geometry>
    </visual>
    <collision name="wheel">
      <origin rpy="0 0 0" xyz="0 0 0"/>
      <geometry>
        <cylinder length="0.0025" radius="0.0065"/>
      </geometry>
    </collision>
  </link>
  <joint name="wheel_subwheel_rl_3" type="continuous">
    <parent link="wheel_rl"/>
    <child link="sub_wheel_rl_3"/>
    <axis xyz="0 0 1"/>
    <origin rpy="0.628319 0 0" xyz="0.007 0.017798374 0.01293127"/>
    <dynamics damping="0.0" friction="42"/>
    <!--
      <limit effort="30" velocity="1" />
-->
  </joint>
  <link name="sub_wheel_rl_4">
    <inertial>
      <origin rpy="0 0 0" xyz="0 0 0"/>
      <mass value="0.001"/>
      <inertia ixx="0.00000001" ixy="0" ixz="0" iyy="0.00000001" iyz="0" izz="0.00000001"/>
    </inertial>
    <visual name="wheel-visual">
      <origin rpy="0 0 0" xyz="0 0 0"/>
      <geometry>
        <cylinder length="0.0025" radius="0.0065"/>
      </geometry>
    </visual>
    <collision name="wheel">
      <origin rpy="0 0 0" xyz="0 0 0"/>
      <geometry>
        <cylinder length="0.0025" radius="0.0065"/>
      </geometry>
    </collision>
  </link>
  <joint name="wheel_subwheel_rl_4" type="continuous">
    <parent link="wheel_rl"/>
    <child link="sub_wheel_rl_4"/>
    <axis xyz="0 0 1"/>
    <origin rpy="0.942478 0 0" xyz="0.007 0.01293127 0.017798374"/>
    <dynamics damping="0.0" friction="42"/>
    <!--
      <limit effort="30" velocity="1" />
-->
  </joint>
  <link name="sub_wheel_rl_5">
    <inertial>
      <origin rpy="0 0 0" xyz="0 0 0"/>
      <mass value="0.001"/>
      <inertia ixx="0.00000001" ixy="0" ixz="0" iyy="0.00000001" iyz="0" izz="0.00000001"/>
    </inertial>
    <visual name="wheel-visual">
      <origin rpy="0 0 0" xyz="0 0 0"/>
      <geometry>
        <cylinder length="0.0025" radius="0.0065"/>
      </geometry>
    </visual>
    <collision name="wheel">
      <origin rpy="0 0 0" xyz="0 0 0"/>
      <geometry>
        <cylinder length="0.0025" radius="0.0065"/>
      </geometry>
    </collision>
  </link>
  <joint name="wheel_subwheel_rl_5" type="continuous">
    <parent link="wheel_rl"/>
    <child link="sub_wheel_rl_5"/>
    <axis xyz="0 0 1"/>
    <origin rpy="1.256637 0 0" xyz="0.007 0.006798374 0.020923254"/>
    <dynamics damping="0.0" friction="42"/>
    <!--
      <limit effort="30" velocity="1" />
-->
  </joint>
  <link name="sub_wheel_rl_6">
    <inertial>
      <origin rpy="0 0 0" xyz="0 0 0"/>
      <mass value="0.001"/>
      <inertia ixx="0.00000001" ixy="0" ixz="0" iyy="0.00000001" iyz="0" izz="0.00000001"/>
    </inertial>
    <visual name="wheel-visual">
      <origin rpy="0 0 0" xyz="0 0 0"/>
      <geometry>
        <cylinder length="0.0025" radius="0.0065"/>
      </geometry>
    </visual>
    <collision name="wheel">
      <origin rpy="0 0 0" xyz="0 0 0"/>
      <geometry>
        <cylinder length="0.0025" radius="0.0065"/>
      </geometry>
    </collision>
  </link>
  <joint name="wheel_subwheel_rl_6" type="continuous">
    <parent link="wheel_rl"/>
    <child link="sub_wheel_rl_6"/>
    <axis xyz="0 0 1"/>
    <origin rpy="1.570796 0 0" xyz="0.007 0.0 0.022"/>
    <dynamics damping="0.0" friction="42"/>
    <!--
      <limit effort="30" velocity="1" />
-->
  </joint>
  <link name="sub_wheel_rl_7">
    <inertial>
      <origin rpy="0 0 0" xyz="0 0 0"/>
      <mass value="0.001"/>
      <inertia ixx="0.00000001" ixy="0" ixz="0" iyy="0.00000001" iyz="0" izz="0.00000001"/>
    </inertial>
    <visual name="wheel-visual">
      <origin rpy="0 0 0" xyz="0 0 0"/>
      <geometry>
        <cylinder length="0.0025" radius="0.0065"/>
      </geometry>
    </visual>
    <collision name="wheel">
      <origin rpy="0 0 0" xyz="0 0 0"/>
      <geometry>
        <cylinder length="0.0025" radius="0.0065"/>
      </geometry>
    </collision>
  </link>
  <joint name="wheel_subwheel_rl_7" type="continuous">
    <parent link="wheel_rl"/>
    <child link="sub_wheel_rl_7"/>
    <axis xyz="0 0 1"/>
    <origin rpy="1.884956 0 0" xyz="0.007 -0.006798374 0.020923254"/>
    <dynamics damping="0.0" friction="42"/>
    <!--
      <limit effort="30" velocity="1" />
-->
  </joint>
  <link name="sub_wheel_rl_8">
    <inertial>
      <origin rpy="0 0 0" xyz="0 0 0"/>
      <mass value="0.001"/>
      <inertia ixx="0.00000001" ixy="0" ixz="0" iyy="0.00000001" iyz="0" izz="0.00000001"/>
    </inertial>
    <visual name="wheel-visual">
      <origin rpy="0 0 0" xyz="0 0 0"/>
      <geometry>
        <cylinder length="0.0025" radius="0.0065"/>
      </geometry>
    </visual>
    <collision name="wheel">
      <origin rpy="0 0 0" xyz="0 0 0"/>
      <geometry>
        <cylinder length="0.0025" radius="0.0065"/>
      </geometry>
    </collision>
  </link>
  <joint name="wheel_subwheel_rl_8" type="continuous">
    <parent link="wheel_rl"/>
    <child link="sub_wheel_rl_8"/>
    <axis xyz="0 0 1"/>
    <origin rpy="2.199115 0 0" xyz="0.007 -0.01293127 0.017798374"/>
    <dynamics damping="0.0" friction="42"/>
    <!--
      <limit effort="30" velocity="1" />
-->
  </joint>
  <link name="sub_wheel_rl_9">
    <inertial>
      <origin rpy="0 0 0" xyz="0 0 0"/>
      <mass value="0.001"/>
      <inertia ixx="0.00000001" ixy="0" ixz="0" iyy="0.00000001" iyz="0" izz="0.00000001"/>
    </inertial>
    <visual name="wheel-visual">
      <origin rpy="0 0 0" xyz="0 0 0"/>
      <geometry>
        <cylinder length="0.0025" radius="0.0065"/>
      </geometry>
    </visual>
    <collision name="wheel">
      <origin rpy="0 0 0" xyz="0 0 0"/>
      <geometry>
        <cylinder length="0.0025" radius="0.0065"/>
      </geometry>
    </collision>
  </link>
  <joint name="wheel_subwheel_rl_9" type="continuous">
    <parent link="wheel_rl"/>
    <child link="sub_wheel_rl_9"/>
    <axis xyz="0 0 1"/>
    <origin rpy="2.513274 0 0" xyz="0.007 -0.017798374 0.01293127"/>
    <dynamics damping="0.0" friction="42"/>
    <!--
      <limit effort="30" velocity="1" />
-->
  </joint>
  <link name="sub_wheel_rl_10">
    <inertial>
      <origin rpy="0 0 0" xyz="0 0 0"/>
      <mass value="0.001"/>
      <inertia ixx="0.00000001" ixy="0" ixz="0" iyy="0.00000001" iyz="0" izz="0.00000001"/>
    </inertial>
    <visual name="wheel-visual">
      <origin rpy="0 0 0" xyz="0 0 0"/>
      <geometry>
        <cylinder length="0.0025" radius="0.0065"/>
      </geometry>
    </visual>
    <collision name="wheel">
      <origin rpy="0 0 0" xyz="0 0 0"/>
      <geometry>
        <cylinder length="0.0025" radius="0.0065"/>
      </geometry>
    </collision>
  </link>
  <joint name="wheel_subwheel_rl_10" type="continuous">
    <parent link="wheel_rl"/>
    <child link="sub_wheel_rl_10"/>
    <axis xyz="0 0 1"/>
    <origin rpy="2.827433 0 0" xyz="0.007 -0.020923254 0.006798374"/>
    <dynamics damping="0.0" friction="42"/>
    <!--
      <limit effort="30" velocity="1" />
-->
  </joint>
  <link name="sub_wheel_rl_11">
    <inertial>
      <origin rpy="0 0 0" xyz="0 0 0"/>
      <mass value="0.001"/>
      <inertia ixx="0.00000001" ixy="0" ixz="0" iyy="0.00000001" iyz="0" izz="0.00000001"/>
    </inertial>
    <visual name="wheel-visual">
      <origin rpy="0 0 0" xyz="0 0 0"/>
      <geometry>
        <cylinder length="0.0025" radius="0.0065"/>
      </geometry>
    </visual>
    <collision name="wheel">
      <origin rpy="0 0 0" xyz="0 0 0"/>
      <geometry>
        <cylinder length="0.0025" radius="0.0065"/>
      </geometry>
    </collision>
  </link>
  <joint name="wheel_subwheel_rl_11" type="continuous">
    <parent link="wheel_rl"/>
    <child link="sub_wheel_rl_11"/>
    <axis xyz="0 0 1"/>
    <origin rpy="3.141593 0 0" xyz="0.007 -0.022 0.0"/>
    <dynamics damping="0.0" friction="42"/>
    <!--
      <limit effort="30" velocity="1" />
-->
  </joint>
  <link name="sub_wheel_rl_12">
    <inertial>
      <origin rpy="0 0 0" xyz="0 0 0"/>
      <mass value="0.001"/>
      <inertia ixx="0.00000001" ixy="0" ixz="0" iyy="0.00000001" iyz="0" izz="0.00000001"/>
    </inertial>
    <visual name="wheel-visual">
      <origin rpy="0 0 0" xyz="0 0 0"/>
      <geometry>
        <cylinder length="0.0025" radius="0.0065"/>
      </geometry>
    </visual>
    <collision name="wheel">
      <origin rpy="0 0 0" xyz="0 0 0"/>
      <geometry>
        <cylinder length="0.0025" radius="0.0065"/>
      </geometry>
    </collision>
  </link>
  <joint name="wheel_subwheel_rl_12" type="continuous">
    <parent link="wheel_rl"/>
    <child link="sub_wheel_rl_12"/>
    <axis xyz="0 0 1"/>
    <origin rpy="3.455752 0 0" xyz="0.007 -0.020923254 -0.006798374"/>
    <dynamics damping="0.0" friction="42"/>
    <!--
      <limit effort="30" velocity="1" />
-->
  </joint>
  <link name="sub_wheel_rl_13">
    <inertial>
      <origin rpy="0 0 0" xyz="0 0 0"/>
      <mass value="0.001"/>
      <inertia ixx="0.00000001" ixy="0" ixz="0" iyy="0.00000001" iyz="0" izz="0.00000001"/>
    </inertial>
    <visual name="wheel-visual">
      <origin rpy="0 0 0" xyz="0 0 0"/>
      <geometry>
        <cylinder length="0.0025" radius="0.0065"/>
      </geometry>
    </visual>
    <collision name="wheel">
      <origin rpy="0 0 0" xyz="0 0 0"/>
      <geometry>
        <cylinder length="0.0025" radius="0.0065"/>
      </geometry>
    </collision>
  </link>
  <joint name="wheel_subwheel_rl_13" type="continuous">
    <parent link="wheel_rl"/>
    <child link="sub_wheel_rl_13"/>
    <axis xyz="0 0 1"/>
    <origin rpy="3.769911 0 0" xyz="0.007 -0.017798374 -0.01293127"/>
    <dynamics damping="0.0" friction="42"/>
    <!--
      <limit effort="30" velocity="1" />
-->
  </joint>
  <link name="sub_wheel_rl_14">
    <inertial>
      <origin rpy="0 0 0" xyz="0 0 0"/>
      <mass value="0.001"/>
      <inertia ixx="0.00000001" ixy="0" ixz="0" iyy="0.00000001" iyz="0" izz="0.00000001"/>
    </inertial>
    <visual name="wheel-visual">
      <origin rpy="0 0 0" xyz="0 0 0"/>
      <geometry>
        <cylinder length="0.0025" radius="0.0065"/>
      </geometry>
    </visual>
    <collision name="wheel">
      <origin rpy="0 0 0" xyz="0 0 0"/>
      <geometry>
        <cylinder length="0.0025" radius="0.0065"/>
      </geometry>
    </collision>
  </link>
  <joint name="wheel_subwheel_rl_14" type="continuous">
    <parent link="wheel_rl"/>
    <child link="sub_wheel_rl_14"/>
    <axis xyz="0 0 1"/>
    <origin rpy="4.08407 0 0" xyz="0.007 -0.01293127 -0.017798374"/>
    <dynamics damping="0.0" friction="42"/>
    <!--
      <limit effort="30" velocity="1" />
-->
  </joint>
  <link name="sub_wheel_rl_15">
    <inertial>
      <origin rpy="0 0 0" xyz="0 0 0"/>
      <mass value="0.001"/>
      <inertia ixx="0.00000001" ixy="0" ixz="0" iyy="0.00000001" iyz="0" izz="0.00000001"/>
    </inertial>
    <visual name="wheel-visual">
      <origin rpy="0 0 0" xyz="0 0 0"/>
      <geometry>
        <cylinder length="0.0025" radius="0.0065"/>
      </geometry>
    </visual>
    <collision name="wheel">
      <origin rpy="0 0 0" xyz="0 0 0"/>
      <geometry>
        <cylinder length="0.0025" radius="0.0065"/>
      </geometry>
    </collision>
  </link>
  <joint name="wheel_subwheel_rl_15" type="continuous">
    <parent link="wheel_rl"/>
    <child link="sub_wheel_rl_15"/>
    <axis xyz="0 0 1"/>
    <origin rpy="4.39823 0 0" xyz="0.007 -0.006798374 -0.020923254"/>
    <dynamics damping="0.0" friction="42"/>
    <!--
      <limit effort="30" velocity="1" />
-->
  </joint>
  <link name="sub_wheel_rl_16">
    <inertial>
      <origin rpy="0 0 0" xyz="0 0 0"/>
      <mass value="0.001"/>
      <inertia ixx="0.00000001" ixy="0" ixz="0" iyy="0.00000001" iyz="0" izz="0.00000001"/>
    </inertial>
    <visual name="wheel-visual">
      <origin rpy="0 0 0" xyz="0 0 0"/>
      <geometry>
        <cylinder length="0.0025" radius="0.0065"/>
      </geometry>
    </visual>
    <collision name="wheel">
      <origin rpy="0 0 0" xyz="0 0 0"/>
      <geometry>
        <cylinder length="0.0025" radius="0.0065"/>
      </geometry>
    </collision>
  </link>
  <joint name="wheel_subwheel_rl_16" type="continuous">
    <parent link="wheel_rl"/>
    <child link="sub_wheel_rl_16"/>
    <axis xyz="0 0 1"/>
    <origin rpy="4.712389 0 0" xyz="0.007 -0.0 -0.022"/>
    <dynamics damping="0.0" friction="42"/>
    <!--
      <limit effort="30" velocity="1" />
-->
  </joint>
  <link name="sub_wheel_rl_17">
    <inertial>
      <origin rpy="0 0 0" xyz="0 0 0"/>
      <mass value="0.001"/>
      <inertia ixx="0.00000001" ixy="0" ixz="0" iyy="0.00000001" iyz="0" izz="0.00000001"/>
    </inertial>
    <visual name="wheel-visual">
      <origin rpy="0 0 0" xyz="0 0 0"/>
      <geometry>
        <cylinder length="0.0025" radius="0.0065"/>
      </geometry>
    </visual>
    <collision name="wheel">
      <origin rpy="0 0 0" xyz="0 0 0"/>
      <geometry>
        <cylinder length="0.0025" radius="0.0065"/>
      </geometry>
    </collision>
  </link>
  <joint name="wheel_subwheel_rl_17" type="continuous">
    <parent link="wheel_rl"/>
    <child link="sub_wheel_rl_17"/>
    <axis xyz="0 0 1"/>
    <origin rpy="5.026548 0 0" xyz="0.007 0.006798374 -0.020923254"/>
    <dynamics damping="0.0" friction="42"/>
    <!--
      <limit effort="30" velocity="1" />
-->
  </joint>
  <link name="sub_wheel_rl_18">
    <inertial>
      <origin rpy="0 0 0" xyz="0 0 0"/>
      <mass value="0.001"/>
      <inertia ixx="0.00000001" ixy="0" ixz="0" iyy="0.00000001" iyz="0" izz="0.00000001"/>
    </inertial>
    <visual name="wheel-visual">
      <origin rpy="0 0 0" xyz="0 0 0"/>
      <geometry>
        <cylinder length="0.0025" radius="0.0065"/>
      </geometry>
    </visual>
    <collision name="wheel">
      <origin rpy="0 0 0" xyz="0 0 0"/>
      <geometry>
        <cylinder length="0.0025" radius="0.0065"/>
      </geometry>
    </collision>
  </link>
  <joint name="wheel_subwheel_rl_18" type="continuous">
    <parent link="wheel_rl"/>
    <child link="sub_wheel_rl_18"/>
    <axis xyz="0 0 1"/>
    <origin rpy="5.340708 0 0" xyz="0.007 0.01293127 -0.017798374"/>
    <dynamics damping="0.0" friction="42"/>
    <!--
      <limit effort="30" velocity="1" />
-->
  </joint>
  <link name="sub_wheel_rl_19">
    <inertial>
      <origin rpy="0 0 0" xyz="0 0 0"/>
      <mass value="0.001"/>
      <inertia ixx="0.00000001" ixy="0" ixz="0" iyy="0.00000001" iyz="0" izz="0.00000001"/>
    </inertial>
    <visual name="wheel-visual">
      <origin rpy="0 0 0" xyz="0 0 0"/>
      <geometry>
        <cylinder length="0.0025" radius="0.0065"/>
      </geometry>
    </visual>
    <collision name="wheel">
      <origin rpy="0 0 0" xyz="0 0 0"/>
      <geometry>
        <cylinder length="0.0025" radius="0.0065"/>
      </geometry>
    </collision>
  </link>
  <joint name="wheel_subwheel_rl_19" type="continuous">
    <parent link="wheel_rl"/>
    <child link="sub_wheel_rl_19"/>
    <axis xyz="0 0 1"/>
    <origin rpy="5.654867 0 0" xyz="0.007 0.017798374 -0.01293127"/>
    <dynamics damping="0.0" friction="42"/>
    <!--
      <limit effort="30" velocity="1" />
-->
  </joint>
  <link name="sub_wheel_rl_20">
    <inertial>
      <origin rpy="0 0 0" xyz="0 0 0"/>
      <mass value="0.001"/>
      <inertia ixx="0.00000001" ixy="0" ixz="0" iyy="0.00000001" iyz="0" izz="0.00000001"/>
    </inertial>
    <visual name="wheel-visual">
      <origin rpy="0 0 0" xyz="0 0 0"/>
      <geometry>
        <cylinder length="0.0025" radius="0.0065"/>
      </geometry>
    </visual>
    <collision name="wheel">
      <origin rpy="0 0 0" xyz="0 0 0"/>
      <geometry>
        <cylinder length="0.0025" radius="0.0065"/>
      </geometry>
    </collision>
  </link>
  <joint name="wheel_subwheel_rl_20" type="continuous">
    <parent link="wheel_rl"/>
    <child link="sub_wheel_rl_20"/>
    <axis xyz="0 0 1"/>
    <origin rpy="5.969026 0 0" xyz="0.007 0.020923254 -0.006798374"/>
    <dynamics damping="0.0" friction="42"/>
    <!--
      <limit effort="30" velocity="1" />
-->
  </joint>
  <transmission name="tran_rl">
    <type>transmission_interface/SimpleTransmission</type>
    <joint name="base_wheel_rl">
      <hardwareInterface>EffortJointInterface</hardwareInterface>
    </joint>
    <actuator name="wheel_rl">
      <hardwareInterface>EffortJointInterface</hardwareInterface>
      <mechanicalReduction>1</mechanicalReduction>
    </actuator>
  </transmission>
  <link name="wheel_rr">
    <inertial>
      <origin rpy="0 1.5707 0" xyz="0.007 0 0"/>
      <mass value="0.05"/>
      <inertia ixx="0.000010" ixy="0" ixz="0" iyy="0.000010" iyz="0" izz="0.000018"/>
    </inertial>
    <!--
      <visual name="wheel-visual" >
        <origin xyz="0 0 0" rpy="0 1.5707 0" />
        <geometry>
          <mesh filename="package://ssl_robot_description/meshes/UBG-Rad.stl"/>
          <cylinder radius="${wheel_radius}" length="${wheel_thickness}" />
        </geometry>
      </visual>
-->
    <!--
      <collision name="wheel">
        <origin xyz="0.005 0 0" rpy="0 1.5707 0" />
        <geometry>
          <cylinder radius="${wheel_radius}" length="${wheel_thickness}" />
        </geometry>
      </collision>
-->
  </link>
  <!--
    <link name="motor_${suffix}">
      <inertial>
        <origin xyz="${robot_wheel_radius-wheel_thickness-0.005} 0 ${wheel_radius}" rpy="0 0 0" />
        <mass value="0.10" />
        <inertia ixx="0.000042" ixy="0" ixz="0" iyy="0.000022" iyz="0" izz="0.000022" />
      </inertial>
      <visual>
        <origin xyz="${robot_wheel_radius-wheel_thickness-0.0005} 0 ${wheel_radius}" rpy="0 0 0" />
        <geometry>
          <box size="0.001 ${wheel_radius*2} ${wheel_radius*2}" />
        </geometry>
      </visual>
    </link>
-->
  <joint name="base_wheel_rr" type="continuous">
    <parent link="base_plate"/>
    <child link="wheel_rr"/>
    <axis xyz="1 0 0"/>
    <!--
      <origin xyz="${robot_wheel_radius} 0 ${wheel_radius-ground_clearance}" rpy="0 0 ${rotation}" />
-->
    <origin rpy="0 0 -2.3562" xyz="-0.0530325 -0.0530325 0.025"/>
    <dynamics damping="0.0" friction="0.01"/>
  </joint>
  <!--
    <joint name="base_motor_${suffix}" type="revolute">
      <parent link="${parent}" />
      <child link="motor_${suffix}" />
      <axis xyz="0 0 1" />
      <limit effort="30" velocity="1.0" lower="${rotation}" upper="${rotation}" />
      <origin xyz="0 0 0" 
              rpy="0 0 0" />
    </joint>
-->
  <link name="sub_wheel_rr_1">
    <inertial>
      <origin rpy="0 0 0" xyz="0 0 0"/>
      <mass value="0.001"/>
      <inertia ixx="0.00000001" ixy="0" ixz="0" iyy="0.00000001" iyz="0" izz="0.00000001"/>
    </inertial>
    <visual name="wheel-visual">
      <origin rpy="0 0 0" xyz="0 0 0"/>
      <geometry>
        <cylinder length="0.0025" radius="0.0065"/>
      </geometry>
    </visual>
    <collision name="wheel">
      <origin rpy="0 0 0" xyz="0 0 0"/>
      <geometry>
        <cylinder length="0.0025" radius="0.0065"/>
      </geometry>
    </collision>
  </link>
  <joint name="wheel_subwheel_rr_1" type="continuous">
    <parent link="wheel_rr"/>
    <child link="sub_wheel_rr_1"/>
    <axis xyz="0 0 1"/>
    <origin rpy="0.0 0 0" xyz="0.007 0.022 0.0"/>
    <dynamics damping="0.0" friction="42"/>
    <!--
      <limit effort="30" velocity="1" />
-->
  </joint>
  <link name="sub_wheel_rr_2">
    <inertial>
      <origin rpy="0 0 0" xyz="0 0 0"/>
      <mass value="0.001"/>
      <inertia ixx="0.00000001" ixy="0" ixz="0" iyy="0.00000001" iyz="0" izz="0.00000001"/>
    </inertial>
    <visual name="wheel-visual">
      <origin rpy="0 0 0" xyz="0 0 0"/>
      <geometry>
        <cylinder length="0.0025" radius="0.0065"/>
      </geometry>
    </visual>
    <collision name="wheel">
      <origin rpy="0 0 0" xyz="0 0 0"/>
      <geometry>
        <cylinder length="0.0025" radius="0.0065"/>
      </geometry>
    </collision>
  </link>
  <joint name="wheel_subwheel_rr_2" type="continuous">
    <parent link="wheel_rr"/>
    <child link="sub_wheel_rr_2"/>
    <axis xyz="0 0 1"/>
    <origin rpy="0.314159 0 0" xyz="0.007 0.020923254 0.006798374"/>
    <dynamics damping="0.0" friction="42"/>
    <!--
      <limit effort="30" velocity="1" />
-->
  </joint>
  <link name="sub_wheel_rr_3">
    <inertial>
      <origin rpy="0 0 0" xyz="0 0 0"/>
      <mass value="0.001"/>
      <inertia ixx="0.00000001" ixy="0" ixz="0" iyy="0.00000001" iyz="0" izz="0.00000001"/>
    </inertial>
    <visual name="wheel-visual">
      <origin rpy="0 0 0" xyz="0 0 0"/>
      <geometry>
        <cylinder length="0.0025" radius="0.0065"/>
      </geometry>
    </visual>
    <collision name="wheel">
      <origin rpy="0 0 0" xyz="0 0 0"/>
      <geometry>
        <cylinder length="0.0025" radius="0.0065"/>
      </geometry>
    </collision>
  </link>
  <joint name="wheel_subwheel_rr_3" type="continuous">
    <parent link="wheel_rr"/>
    <child link="sub_wheel_rr_3"/>
    <axis xyz="0 0 1"/>
    <origin rpy="0.628319 0 0" xyz="0.007 0.017798374 0.01293127"/>
    <dynamics damping="0.0" friction="42"/>
    <!--
      <limit effort="30" velocity="1" />
-->
  </joint>
  <link name="sub_wheel_rr_4">
    <inertial>
      <origin rpy="0 0 0" xyz="0 0 0"/>
      <mass value="0.001"/>
      <inertia ixx="0.00000001" ixy="0" ixz="0" iyy="0.00000001" iyz="0" izz="0.00000001"/>
    </inertial>
    <visual name="wheel-visual">
      <origin rpy="0 0 0" xyz="0 0 0"/>
      <geometry>
        <cylinder length="0.0025" radius="0.0065"/>
      </geometry>
    </visual>
    <collision name="wheel">
      <origin rpy="0 0 0" xyz="0 0 0"/>
      <geometry>
        <cylinder length="0.0025" radius="0.0065"/>
      </geometry>
    </collision>
  </link>
  <joint name="wheel_subwheel_rr_4" type="continuous">
    <parent link="wheel_rr"/>
    <child link="sub_wheel_rr_4"/>
    <axis xyz="0 0 1"/>
    <origin rpy="0.942478 0 0" xyz="0.007 0.01293127 0.017798374"/>
    <dynamics damping="0.0" friction="42"/>
    <!--
      <limit effort="30" velocity="1" />
-->
  </joint>
  <link name="sub_wheel_rr_5">
    <inertial>
      <origin rpy="0 0 0" xyz="0 0 0"/>
      <mass value="0.001"/>
      <inertia ixx="0.00000001" ixy="0" ixz="0" iyy="0.00000001" iyz="0" izz="0.00000001"/>
    </inertial>
    <visual name="wheel-visual">
      <origin rpy="0 0 0" xyz="0 0 0"/>
      <geometry>
        <cylinder length="0.0025" radius="0.0065"/>
      </geometry>
    </visual>
    <collision name="wheel">
      <origin rpy="0 0 0" xyz="0 0 0"/>
      <geometry>
        <cylinder length="0.0025" radius="0.0065"/>
      </geometry>
    </collision>
  </link>
  <joint name="wheel_subwheel_rr_5" type="continuous">
    <parent link="wheel_rr"/>
    <child link="sub_wheel_rr_5"/>
    <axis xyz="0 0 1"/>
    <origin rpy="1.256637 0 0" xyz="0.007 0.006798374 0.020923254"/>
    <dynamics damping="0.0" friction="42"/>
    <!--
      <limit effort="30" velocity="1" />
-->
  </joint>
  <link name="sub_wheel_rr_6">
    <inertial>
      <origin rpy="0 0 0" xyz="0 0 0"/>
      <mass value="0.001"/>
      <inertia ixx="0.00000001" ixy="0" ixz="0" iyy="0.00000001" iyz="0" izz="0.00000001"/>
    </inertial>
    <visual name="wheel-visual">
      <origin rpy="0 0 0" xyz="0 0 0"/>
      <geometry>
        <cylinder length="0.0025" radius="0.0065"/>
      </geometry>
    </visual>
    <collision name="wheel">
      <origin rpy="0 0 0" xyz="0 0 0"/>
      <geometry>
        <cylinder length="0.0025" radius="0.0065"/>
      </geometry>
    </collision>
  </link>
  <joint name="wheel_subwheel_rr_6" type="continuous">
    <parent link="wheel_rr"/>
    <child link="sub_wheel_rr_6"/>
    <axis xyz="0 0 1"/>
    <origin rpy="1.570796 0 0" xyz="0.007 0.0 0.022"/>
    <dynamics damping="0.0" friction="42"/>
    <!--
      <limit effort="30" velocity="1" />
-->
  </joint>
  <link name="sub_wheel_rr_7">
    <inertial>
      <origin rpy="0 0 0" xyz="0 0 0"/>
      <mass value="0.001"/>
      <inertia ixx="0.00000001" ixy="0" ixz="0" iyy="0.00000001" iyz="0" izz="0.00000001"/>
    </inertial>
    <visual name="wheel-visual">
      <origin rpy="0 0 0" xyz="0 0 0"/>
      <geometry>
        <cylinder length="0.0025" radius="0.0065"/>
      </geometry>
    </visual>
    <collision name="wheel">
      <origin rpy="0 0 0" xyz="0 0 0"/>
      <geometry>
        <cylinder length="0.0025" radius="0.0065"/>
      </geometry>
    </collision>
  </link>
  <joint name="wheel_subwheel_rr_7" type="continuous">
    <parent link="wheel_rr"/>
    <child link="sub_wheel_rr_7"/>
    <axis xyz="0 0 1"/>
    <origin rpy="1.884956 0 0" xyz="0.007 -0.006798374 0.020923254"/>
    <dynamics damping="0.0" friction="42"/>
    <!--
      <limit effort="30" velocity="1" />
-->
  </joint>
  <link name="sub_wheel_rr_8">
    <inertial>
      <origin rpy="0 0 0" xyz="0 0 0"/>
      <mass value="0.001"/>
      <inertia ixx="0.00000001" ixy="0" ixz="0" iyy="0.00000001" iyz="0" izz="0.00000001"/>
    </inertial>
    <visual name="wheel-visual">
      <origin rpy="0 0 0" xyz="0 0 0"/>
      <geometry>
        <cylinder length="0.0025" radius="0.0065"/>
      </geometry>
    </visual>
    <collision name="wheel">
      <origin rpy="0 0 0" xyz="0 0 0"/>
      <geometry>
        <cylinder length="0.0025" radius="0.0065"/>
      </geometry>
    </collision>
  </link>
  <joint name="wheel_subwheel_rr_8" type="continuous">
    <parent link="wheel_rr"/>
    <child link="sub_wheel_rr_8"/>
    <axis xyz="0 0 1"/>
    <origin rpy="2.199115 0 0" xyz="0.007 -0.01293127 0.017798374"/>
    <dynamics damping="0.0" friction="42"/>
    <!--
      <limit effort="30" velocity="1" />
-->
  </joint>
  <link name="sub_wheel_rr_9">
    <inertial>
      <origin rpy="0 0 0" xyz="0 0 0"/>
      <mass value="0.001"/>
      <inertia ixx="0.00000001" ixy="0" ixz="0" iyy="0.00000001" iyz="0" izz="0.00000001"/>
    </inertial>
    <visual name="wheel-visual">
      <origin rpy="0 0 0" xyz="0 0 0"/>
      <geometry>
        <cylinder length="0.0025" radius="0.0065"/>
      </geometry>
    </visual>
    <collision name="wheel">
      <origin rpy="0 0 0" xyz="0 0 0"/>
      <geometry>
        <cylinder length="0.0025" radius="0.0065"/>
      </geometry>
    </collision>
  </link>
  <joint name="wheel_subwheel_rr_9" type="continuous">
    <parent link="wheel_rr"/>
    <child link="sub_wheel_rr_9"/>
    <axis xyz="0 0 1"/>
    <origin rpy="2.513274 0 0" xyz="0.007 -0.017798374 0.01293127"/>
    <dynamics damping="0.0" friction="42"/>
    <!--
      <limit effort="30" velocity="1" />
-->
  </joint>
  <link name="sub_wheel_rr_10">
    <inertial>
      <origin rpy="0 0 0" xyz="0 0 0"/>
      <mass value="0.001"/>
      <inertia ixx="0.00000001" ixy="0" ixz="0" iyy="0.00000001" iyz="0" izz="0.00000001"/>
    </inertial>
    <visual name="wheel-visual">
      <origin rpy="0 0 0" xyz="0 0 0"/>
      <geometry>
        <cylinder length="0.0025" radius="0.0065"/>
      </geometry>
    </visual>
    <collision name="wheel">
      <origin rpy="0 0 0" xyz="0 0 0"/>
      <geometry>
        <cylinder length="0.0025" radius="0.0065"/>
      </geometry>
    </collision>
  </link>
  <joint name="wheel_subwheel_rr_10" type="continuous">
    <parent link="wheel_rr"/>
    <child link="sub_wheel_rr_10"/>
    <axis xyz="0 0 1"/>
    <origin rpy="2.827433 0 0" xyz="0.007 -0.020923254 0.006798374"/>
    <dynamics damping="0.0" friction="42"/>
    <!--
      <limit effort="30" velocity="1" />
-->
  </joint>
  <link name="sub_wheel_rr_11">
    <inertial>
      <origin rpy="0 0 0" xyz="0 0 0"/>
      <mass value="0.001"/>
      <inertia ixx="0.00000001" ixy="0" ixz="0" iyy="0.00000001" iyz="0" izz="0.00000001"/>
    </inertial>
    <visual name="wheel-visual">
      <origin rpy="0 0 0" xyz="0 0 0"/>
      <geometry>
        <cylinder length="0.0025" radius="0.0065"/>
      </geometry>
    </visual>
    <collision name="wheel">
      <origin rpy="0 0 0" xyz="0 0 0"/>
      <geometry>
        <cylinder length="0.0025" radius="0.0065"/>
      </geometry>
    </collision>
  </link>
  <joint name="wheel_subwheel_rr_11" type="continuous">
    <parent link="wheel_rr"/>
    <child link="sub_wheel_rr_11"/>
    <axis xyz="0 0 1"/>
    <origin rpy="3.141593 0 0" xyz="0.007 -0.022 0.0"/>
    <dynamics damping="0.0" friction="42"/>
    <!--
      <limit effort="30" velocity="1" />
-->
  </joint>
  <link name="sub_wheel_rr_12">
    <inertial>
      <origin rpy="0 0 0" xyz="0 0 0"/>
      <mass value="0.001"/>
      <inertia ixx="0.00000001" ixy="0" ixz="0" iyy="0.00000001" iyz="0" izz="0.00000001"/>
    </inertial>
    <visual name="wheel-visual">
      <origin rpy="0 0 0" xyz="0 0 0"/>
      <geometry>
        <cylinder length="0.0025" radius="0.0065"/>
      </geometry>
    </visual>
    <collision name="wheel">
      <origin rpy="0 0 0" xyz="0 0 0"/>
      <geometry>
        <cylinder length="0.0025" radius="0.0065"/>
      </geometry>
    </collision>
  </link>
  <joint name="wheel_subwheel_rr_12" type="continuous">
    <parent link="wheel_rr"/>
    <child link="sub_wheel_rr_12"/>
    <axis xyz="0 0 1"/>
    <origin rpy="3.455752 0 0" xyz="0.007 -0.020923254 -0.006798374"/>
    <dynamics damping="0.0" friction="42"/>
    <!--
      <limit effort="30" velocity="1" />
-->
  </joint>
  <link name="sub_wheel_rr_13">
    <inertial>
      <origin rpy="0 0 0" xyz="0 0 0"/>
      <mass value="0.001"/>
      <inertia ixx="0.00000001" ixy="0" ixz="0" iyy="0.00000001" iyz="0" izz="0.00000001"/>
    </inertial>
    <visual name="wheel-visual">
      <origin rpy="0 0 0" xyz="0 0 0"/>
      <geometry>
        <cylinder length="0.0025" radius="0.0065"/>
      </geometry>
    </visual>
    <collision name="wheel">
      <origin rpy="0 0 0" xyz="0 0 0"/>
      <geometry>
        <cylinder length="0.0025" radius="0.0065"/>
      </geometry>
    </collision>
  </link>
  <joint name="wheel_subwheel_rr_13" type="continuous">
    <parent link="wheel_rr"/>
    <child link="sub_wheel_rr_13"/>
    <axis xyz="0 0 1"/>
    <origin rpy="3.769911 0 0" xyz="0.007 -0.017798374 -0.01293127"/>
    <dynamics damping="0.0" friction="42"/>
    <!--
      <limit effort="30" velocity="1" />
-->
  </joint>
  <link name="sub_wheel_rr_14">
    <inertial>
      <origin rpy="0 0 0" xyz="0 0 0"/>
      <mass value="0.001"/>
      <inertia ixx="0.00000001" ixy="0" ixz="0" iyy="0.00000001" iyz="0" izz="0.00000001"/>
    </inertial>
    <visual name="wheel-visual">
      <origin rpy="0 0 0" xyz="0 0 0"/>
      <geometry>
        <cylinder length="0.0025" radius="0.0065"/>
      </geometry>
    </visual>
    <collision name="wheel">
      <origin rpy="0 0 0" xyz="0 0 0"/>
      <geometry>
        <cylinder length="0.0025" radius="0.0065"/>
      </geometry>
    </collision>
  </link>
  <joint name="wheel_subwheel_rr_14" type="continuous">
    <parent link="wheel_rr"/>
    <child link="sub_wheel_rr_14"/>
    <axis xyz="0 0 1"/>
    <origin rpy="4.08407 0 0" xyz="0.007 -0.01293127 -0.017798374"/>
    <dynamics damping="0.0" friction="42"/>
    <!--
      <limit effort="30" velocity="1" />
-->
  </joint>
  <link name="sub_wheel_rr_15">
    <inertial>
      <origin rpy="0 0 0" xyz="0 0 0"/>
      <mass value="0.001"/>
      <inertia ixx="0.00000001" ixy="0" ixz="0" iyy="0.00000001" iyz="0" izz="0.00000001"/>
    </inertial>
    <visual name="wheel-visual">
      <origin rpy="0 0 0" xyz="0 0 0"/>
      <geometry>
        <cylinder length="0.0025" radius="0.0065"/>
      </geometry>
    </visual>
    <collision name="wheel">
      <origin rpy="0 0 0" xyz="0 0 0"/>
      <geometry>
        <cylinder length="0.0025" radius="0.0065"/>
      </geometry>
    </collision>
  </link>
  <joint name="wheel_subwheel_rr_15" type="continuous">
    <parent link="wheel_rr"/>
    <child link="sub_wheel_rr_15"/>
    <axis xyz="0 0 1"/>
    <origin rpy="4.39823 0 0" xyz="0.007 -0.006798374 -0.020923254"/>
    <dynamics damping="0.0" friction="42"/>
    <!--
      <limit effort="30" velocity="1" />
-->
  </joint>
  <link name="sub_wheel_rr_16">
    <inertial>
      <origin rpy="0 0 0" xyz="0 0 0"/>
      <mass value="0.001"/>
      <inertia ixx="0.00000001" ixy="0" ixz="0" iyy="0.00000001" iyz="0" izz="0.00000001"/>
    </inertial>
    <visual name="wheel-visual">
      <origin rpy="0 0 0" xyz="0 0 0"/>
      <geometry>
        <cylinder length="0.0025" radius="0.0065"/>
      </geometry>
    </visual>
    <collision name="wheel">
      <origin rpy="0 0 0" xyz="0 0 0"/>
      <geometry>
        <cylinder length="0.0025" radius="0.0065"/>
      </geometry>
    </collision>
  </link>
  <joint name="wheel_subwheel_rr_16" type="continuous">
    <parent link="wheel_rr"/>
    <child link="sub_wheel_rr_16"/>
    <axis xyz="0 0 1"/>
    <origin rpy="4.712389 0 0" xyz="0.007 -0.0 -0.022"/>
    <dynamics damping="0.0" friction="42"/>
    <!--
      <limit effort="30" velocity="1" />
-->
  </joint>
  <link name="sub_wheel_rr_17">
    <inertial>
      <origin rpy="0 0 0" xyz="0 0 0"/>
      <mass value="0.001"/>
      <inertia ixx="0.00000001" ixy="0" ixz="0" iyy="0.00000001" iyz="0" izz="0.00000001"/>
    </inertial>
    <visual name="wheel-visual">
      <origin rpy="0 0 0" xyz="0 0 0"/>
      <geometry>
        <cylinder length="0.0025" radius="0.0065"/>
      </geometry>
    </visual>
    <collision name="wheel">
      <origin rpy="0 0 0" xyz="0 0 0"/>
      <geometry>
        <cylinder length="0.0025" radius="0.0065"/>
      </geometry>
    </collision>
  </link>
  <joint name="wheel_subwheel_rr_17" type="continuous">
    <parent link="wheel_rr"/>
    <child link="sub_wheel_rr_17"/>
    <axis xyz="0 0 1"/>
    <origin rpy="5.026548 0 0" xyz="0.007 0.006798374 -0.020923254"/>
    <dynamics damping="0.0" friction="42"/>
    <!--
      <limit effort="30" velocity="1" />
-->
  </joint>
  <link name="sub_wheel_rr_18">
    <inertial>
      <origin rpy="0 0 0" xyz="0 0 0"/>
      <mass value="0.001"/>
      <inertia ixx="0.00000001" ixy="0" ixz="0" iyy="0.00000001" iyz="0" izz="0.00000001"/>
    </inertial>
    <visual name="wheel-visual">
      <origin rpy="0 0 0" xyz="0 0 0"/>
      <geometry>
        <cylinder length="0.0025" radius="0.0065"/>
      </geometry>
    </visual>
    <collision name="wheel">
      <origin rpy="0 0 0" xyz="0 0 0"/>
      <geometry>
        <cylinder length="0.0025" radius="0.0065"/>
      </geometry>
    </collision>
  </link>
  <joint name="wheel_subwheel_rr_18" type="continuous">
    <parent link="wheel_rr"/>
    <child link="sub_wheel_rr_18"/>
    <axis xyz="0 0 1"/>
    <origin rpy="5.340708 0 0" xyz="0.007 0.01293127 -0.017798374"/>
    <dynamics damping="0.0" friction="42"/>
    <!--
      <limit effort="30" velocity="1" />
-->
  </joint>
  <link name="sub_wheel_rr_19">
    <inertial>
      <origin rpy="0 0 0" xyz="0 0 0"/>
      <mass value="0.001"/>
      <inertia ixx="0.00000001" ixy="0" ixz="0" iyy="0.00000001" iyz="0" izz="0.00000001"/>
    </inertial>
    <visual name="wheel-visual">
      <origin rpy="0 0 0" xyz="0 0 0"/>
      <geometry>
        <cylinder length="0.0025" radius="0.0065"/>
      </geometry>
    </visual>
    <collision name="wheel">
      <origin rpy="0 0 0" xyz="0 0 0"/>
      <geometry>
        <cylinder length="0.0025" radius="0.0065"/>
      </geometry>
    </collision>
  </link>
  <joint name="wheel_subwheel_rr_19" type="continuous">
    <parent link="wheel_rr"/>
    <child link="sub_wheel_rr_19"/>
    <axis xyz="0 0 1"/>
    <origin rpy="5.654867 0 0" xyz="0.007 0.017798374 -0.01293127"/>
    <dynamics damping="0.0" friction="42"/>
    <!--
      <limit effort="30" velocity="1" />
-->
  </joint>
  <link name="sub_wheel_rr_20">
    <inertial>
      <origin rpy="0 0 0" xyz="0 0 0"/>
      <mass value="0.001"/>
      <inertia ixx="0.00000001" ixy="0" ixz="0" iyy="0.00000001" iyz="0" izz="0.00000001"/>
    </inertial>
    <visual name="wheel-visual">
      <origin rpy="0 0 0" xyz="0 0 0"/>
      <geometry>
        <cylinder length="0.0025" radius="0.0065"/>
      </geometry>
    </visual>
    <collision name="wheel">
      <origin rpy="0 0 0" xyz="0 0 0"/>
      <geometry>
        <cylinder length="0.0025" radius="0.0065"/>
      </geometry>
    </collision>
  </link>
  <joint name="wheel_subwheel_rr_20" type="continuous">
    <parent link="wheel_rr"/>
    <child link="sub_wheel_rr_20"/>
    <axis xyz="0 0 1"/>
    <origin rpy="5.969026 0 0" xyz="0.007 0.020923254 -0.006798374"/>
    <dynamics damping="0.0" friction="42"/>
    <!--
      <limit effort="30" velocity="1" />
-->
  </joint>
  <transmission name="tran_rr">
    <type>transmission_interface/SimpleTransmission</type>
    <joint name="base_wheel_rr">
      <hardwareInterface>EffortJointInterface</hardwareInterface>
    </joint>
    <actuator name="wheel_rr">
      <hardwareInterface>EffortJointInterface</hardwareInterface>
      <mechanicalReduction>1</mechanicalReduction>
    </actuator>
  </transmission>
</robot>

