<?xml version="1.0"?>
<robot xmlns:xacro="http://www.ros.org/wiki/xacro">
  <xacro:property name="sub_wheel_radius" value="0.0065" />
  <xacro:property name="sub_wheel_thickness" value="0.0025" />
  
  <xacro:macro name="sub_wheel" params="suffix parent origin_x origin_y rotation">
    
    <link name="sub_wheel_${suffix}">
      <inertial>
        <origin xyz="0 0 0" rpy="0 0 0" />
        <mass value="0.001" />
        <inertia ixx="0.0000625521" ixy="0" ixz="0" iyy="0.0000625521" iyz="0" izz="0.0001250000" />
<!--
        <mass value="0.001" />
        <inertia ixx="0.000000005" ixy="0" ixz="0" iyy="0.000000005" iyz="0" izz="0.000000008" />
-->
      </inertial>
      
      <collision>
        <origin xyz="0 0 0" rpy="0 0 0" />
        <geometry>
          <cylinder radius="${sub_wheel_radius}" length="${sub_wheel_thickness}" />
        </geometry>
      </collision>
    </link>
                  
    <joint name="wheel_subwheel_${suffix}" type="continuous">
      <parent link="${parent}" />
      <child link="sub_wheel_${suffix}" />
      <axis xyz="0 0 1" />
      <origin xyz="0.007 ${origin_x} ${origin_y}" rpy="${rotation} 0 0" />
      <dynamics damping="0.001" friction="0.0" />
    </joint>
  </xacro:macro>
</robot>
